Workbook

Sheet Глубина-день
A1: Сетевой график "Глубина-день"
B2: Определение | D2: Конструкция скважины | K2: Начальные и прогнозные параметры
B3: Компания | C3: ООО "Газпромнефть-Хантос" | D3: Проект | E3: Забой | K3: Начало бурения | N3: 45489.208
B4: Месторождение | C4: Южно-Приобское | D4: Секция | E4: План | H4: Факт | I4: св, шт | J4: ОК, шт | K4: План окончания бурения | N4: =J89 -> 45516.071
B5: Кустовая площадка | C5: 112А.1 | D5: 323.9 | E5: 80 | J5: =ROUNDUP((E5-5)/11.3,0) -> 7 | K5: Факт/прогноз | N5: =O89 -> 45516.375
B6: Скважина № | C6: 46626 | D6: 244.5 | E6: 1500 | I6: =ROUNDUP((E6-E5)/25.5,0) -> 56 | J6: =ROUNDUP((E6-E5-5)/11.3,0) -> 126 | K6: БП | N6: =N3+R90 -> 45516.071
B7: Тип скважины | C7: ГС | D7: 177.8 | E7: 3300 | I7: =ROUNDUP((E7-E6)/25.5,0) -> 71 | J7: =ROUNDUP((E7-E6-5)/11.3,0) -> 159 | K7: План, сут* | N7: =N4-N3 -> 26.8625
B8: Руководитель направления | C8: Тырин Владимир Олегович | D8: 114 | E8: 4449 | I8: =ROUNDUP((E8-E7)/25.5,0) -> 46 | J8: =ROUNDUP((E8-E7-5)/11.3,0) -> 102 | K8: Факт/прогноз, сут | N8: =N5-N3 -> 27.166667
K9: БП, сут | N9: =N6-N3 -> 26.8625 | W9: ПС, сут | X9: =SUM(I49:I52)/24 -> 0.70833333
D10: Длина ГС | E10: =E8-E7 -> 1149 | H10: =H8-H7 -> 0 | K10: Скорость бурения, сут/1000м | L10: План | N10: =N7/E13*1000 -> 6.0378737 | W10: ГС, сут/1000 м | X10: =(N7-X9)/E8*1000 -> 5.8786619
D11: Пилот №1/точка срезки/Длина | G11: =E11-F11 -> 0 | J11: 0 | L11: Факт+Прогноз | N11: =N8/E13*1000 -> 6.1062411
D12: Пилот №2/точка срезки/Длина | G12: =E12-F12 -> 0 | J12: 0 | L12: БП | N12: =N9/E13*1000 -> 6.0378737
D13: Проходка | E13: =E8+G11+G12 -> 4449 | K13: Отклон.от ЦО для бонуса, сут. | N13: =N5-N4 -> 0.30416667
D14: Индекс сложности | K14: Прогноз % времени на ТО БУ | N14: ='реестр НПВ'!M56/('Глубина-день'!N8*24-'реестр НПВ'!M63) -> 0
D15: Зимний коэффициент | E15: 1 | K15: *Плановое время учитывает 5% времени на ТО БУ
A17: Операции | H17: План | K17: Факт | Q17: БП | S17: Мероприятия
A18: # | B18: Операции | C18: Описание | E18: ОК | F18: Интервал | H18: Забой, м | I18: Время | J18: Окончание | K18: Забой, м | L18: Время Факт, ч | M18: НПВ, ч | N18: Откл | O18: Окончание | P18: Примечание | Q18: Забой, м | R18: Время | S18: Описание
F19: от | G19: до | O19: Факт/Прогноз
A20: 1 | B20: КНБК | C20: Сборка роторной КНБК | E20: 324 | F20: 0 | H20: =G20 -> 0 | I20: 0.5 | J20: =N3+I20/24 -> 45489.229 | K20: 0 | L20: 0.5 | N20: =IF(L20="","",L20-I20) -> 0 | O20: =IF(L20<>"",N3+L20/24,N3+I20/24) -> 45489.229 | Q20: =H20 -> 0 | R20: =I20 -> 0.5
A21: =A20+1 -> 2 | B21: Бурение | C21: Бурение под направление | E21: =E20 -> 324 | F21: 0 | G21: 80 | H21: =G21 -> 80 | I21: 2 | J21: =IF(I21<>"",J20+I21/24,"") -> 45489.312 | K21: 80 | L21: 2 | N21: =IF(L21="","",L21-I21) -> 0 | O21: =IF(L21<>"",O20+L21/24,O20+I21/24) -> 45489.312 | Q21: =H21 -> 80 | R21: =I21 -> 2
A22: =A21+1 -> 3 | B22: Шаблонирование / проработка | C22: Шаблонировка пробуренного интервала + промывка на забое+ подъем КНБК | E22: =E21 -> 324 | F22: 0 | G22: 80 | H22: =H21 -> 80 | I22: 1 | J22: =IF(I22<>"",J21+I22/24,"") -> 45489.354 | K22: 80 | L22: 1 | N22: =IF(L22="","",L22-I22) -> 0 | O22: =IF(L22<>"",O21+L22/24,O21+I22/24) -> 45489.354 | Q22: =H22 -> 80 | R22: =I22 -> 1
A23: =A22+1 -> 4 | B23: КНБК | C23: Разборка КНБК | E23: =E22 -> 324 | H23: =H22 -> 80 | I23: 0.5 | J23: =IF(I23<>"",J22+I23/24,"") -> 45489.375 | K23: 80 | L23: 0.5 | N23: =IF(L23="","",L23-I23) -> 0 | O23: =IF(L23<>"",O22+L23/24,O22+I23/24) -> 45489.375 | Q23: =H23 -> 80 | R23: =I23 -> 0.5
A24: =A23+1 -> 5 | B24: Подготовительные работы | C24: ПР к спуску направления 324мм | E24: =E23 -> 324 | H24: =H23 -> 80 | I24: 1 | J24: =IF(I24<>"",J23+I24/24,"") -> 45489.417 | K24: 80 | L24: 1 | N24: =IF(L24="","",L24-I24) -> 0 | O24: =IF(L24<>"",O23+L24/24,O23+I24/24) -> 45489.417 | Q24: =H24 -> 80 | R24: =I24 -> 1
A25: =A24+1 -> 6 | B25: Крепление | C25: Спуск направления 324мм | E25: =E24 -> 324 | F25: 0 | G25: 80 | H25: =H24 -> 80 | I25: 2 | J25: =IF(I25<>"",J24+I25/24,"") -> 45489.5 | K25: 80 | L25: 2 | N25: =IF(L25="","",L25-I25) -> 0 | O25: =IF(L25<>"",O24+L25/24,O24+I25/24) -> 45489.5 | Q25: =H25 -> 80 | R25: =I25 -> 2
A26: =A25+1 -> 7 | B26: Циркуляция и Обработка БР | C26: Промывка перед цементажем | E26: =E25 -> 324 | H26: =H25 -> 80 | I26: 0.5 | J26: =IF(I26<>"",J25+I26/24,"") -> 45489.521 | K26: 80 | L26: 0.5 | N26: =IF(L26="","",L26-I26) -> 0 | O26: =IF(L26<>"",O25+L26/24,O25+I26/24) -> 45489.521 | Q26: =H26 -> 80 | R26: =I26 -> 0.5
A27: =A26+1 -> 8 | B27: Крепление | C27: Цементаж направления 324мм | E27: =E26 -> 324 | H27: =H26 -> 80 | I27: 1.5 | J27: =IF(I27<>"",J26+I27/24,"") -> 45489.583 | K27: 80 | L27: 1.5 | N27: =IF(L27="","",L27-I27) -> 0 | O27: =IF(L27<>"",O26+L27/24,O26+I27/24) -> 45489.583 | P27: БК-79м. ЦКОД-78,20м. | Q27: =H27 -> 80 | R27: =I27 -> 1.5
A28: =A27+1 -> 9 | B28: ОЗЦ | C28: ОЗЦ. Оборудование устья. Сборка СБТ-127мм (1500м) | E28: =E27 -> 324 | H28: =H27 -> 80 | I28: 8 | J28: =IF(I28<>"",J27+I28/24,"") -> 45489.917 | K28: 80 | L28: 8 | N28: =IF(L28="","",L28-I28) -> 0 | O28: =IF(L28<>"",O27+L28/24,O27+I28/24) -> 45489.917 | Q28: =H28 -> 80 | R28: =I28 -> 8 | Y28: ч
A29: =A28+1 -> 10 | B29: СПО | C29: Сборка БИ (1500м) с установкой на подсвечник | E29: =E28 -> 324 | H29: =H28 -> 80 | I29: 12 | J29: =IF(I29<>"",J28+I29/24,"") -> 45490.417 | K29: 80 | L29: 9 | N29: =IF(L29="","",L29-I29) -> -3 | O29: =IF(L29<>"",O28+L29/24,O28+I29/24) -> 45490.292 | Q29: =H29 -> 80 | R29: =I29 -> 12 | U29: =60/(3+3)*12.5 -> 125 | V29: =(G29-F29)/I29 -> 0 | W29: =(G29-F29)/L29 -> 0 | Y29: =(G29-F29)/U29 -> 0
A30: =A29+1 -> 11 | B30: КНБК | C30: Сборка КНБК для бурения | E30: =D6 -> 244.5 | H30: =H29 -> 80 | I30: 3 | J30: =IF(I30<>"",J29+I30/24,"") -> 45490.542 | K30: 80 | L30: 2.5 | N30: =IF(L30="","",L30-I30) -> -0.5 | O30: =IF(L30<>"",O29+L30/24,O29+I30/24) -> 45490.396 | Q30: =H30 -> 80 | R30: =I30 -> 3
A31: =A30+1 -> 12 | B31: СПО | C31: Cпуск КНБК со сборкой БИ с мостков | E31: =E30 -> 244.5 | F31: 0 | G31: 80 | H31: =H30 -> 80 | I31: 0.5 | J31: =IF(I31<>"",J30+I31/24,"") -> 45490.562 | K31: 80 | L31: 0.25 | N31: =IF(L31="","",L31-I31) -> -0.25 | O31: =IF(L31<>"",O30+L31/24,O30+I31/24) -> 45490.406 | Q31: =H31 -> 80 | R31: =I31 -> 0.5 | AE31: м/ч бур
A32: =A31+1 -> 13 | B32: Бурение | C32: Разбурка оснастки (ЦКОД, цем.стакан, БК), замена раствора | E32: =E31 -> 244.5 | F32: 75 | G32: 81 | H32: =G32 -> 81 | I32: 1 | J32: =IF(I32<>"",J31+I32/24,"") -> 45490.604 | K32: 80 | L32: 1 | N32: =IF(L32="","",L32-I32) -> 0 | O32: =IF(L32<>"",O31+L32/24,O31+I32/24) -> 45490.448 | Q32: =H32 -> 81 | R32: =I32 -> 1 | U32: Н | V32: П | W32: Ф | Y32: св | Z32: наращ | AA32: замер | AB32: ориент | AC32: Прор | AD32: пром | AE32: 80 | AG32: сум бур
A33: =A32+1 -> 14 | B33: Вспомогательные работы | C33: Чистка ЦСГО | E33: 245 | H33: =H32 -> 81 | I33: 1 | J33: =IF(I33<>"",J32+I33/24,"") -> 45490.646 | K33: 80 | L33: 0.5 | N33: =IF(L33="","",L33-I33) -> -0.5 | O33: =IF(L33<>"",O32+L33/24,O32+I33/24) -> 45490.469 | Q33: =H33 -> 81 | R33: =I33 -> 1 | U33: 32 | V33: =(G33-F33)/I33 -> 0 | W33: =(K33-K32)/(L33-M33) -> 0 | Y33: =(G33-F33)/25.5 -> 0 | Z33: =Y33*0.15*$E$15 -> 0 | AA33: =Y33*5/60 -> 0 | AB33: =(G33-F33)*0.33/8*5/60 -> 0 | AD33: =(300^2-127^2)*3.14/4/10^6*200/70/60*1000 -> 2.7613683 | AE33: =(G33-F33)/AE32 -> 0 | AG33: =SUM(Z33:AE33) -> 2.7613683
A34: =A33+1 -> 15 | B34: Бурение | C34: Бурение под кондуктор (наращивание с мостков) | E34: =E33 -> 245 | F34: 81 | G34: =E6 -> 1500 | H34: =G34 -> 1500 | I34: 45 | J34: =IF(I34<>"",J33+I34/24,"") -> 45492.521 | K34: 1500 | L34: 45 | M34: 1.75 | N34: =IF(L34="","",L34-I34) -> 0 | O34: =IF(L34<>"",O33+L34/24,O33+I34/24) -> 45492.344 | P34: НПВ №1 Ремонт.Замена опорной втулки на БН№1 (1,75ч). | Q34: =H34 -> 1500 | R34: =I34 -> 45 | Y34: ч
A35: =A34+1 -> 16 | B35: Циркуляция и Обработка БР | C35: Промывка на забое, продувка | E35: =E34 -> 245 | H35: =H34 -> 1500 | I35: 2 | J35: =IF(I35<>"",J34+I35/24,"") -> 45492.604 | K35: 1500 | L35: 2 | N35: =IF(L35="","",L35-I35) -> 0 | O35: =IF(L35<>"",O34+L35/24,O34+I35/24) -> 45492.427 | Q35: =H35 -> 1500 | R35: =I35 -> 2 | U35: 200 | V35: =(G35-F35)/I35 -> 0 | W35: =(K35-K32)/(L35-M35) -> 710 | Y35: =ROUNDDOWN(0.089*$E$15*(F35-G35)/25.5,2) -> 0
A36: =A35+1 -> 17 | B36: СПО | C36: Шаблонирование подъём КНБК | E36: =E35 -> 245 | F36: =G34 -> 1500 | G36: 80 | H36: =H35 -> 1500 | I36: 8 | J36: =IF(I36<>"",J35+I36/24,"") -> 45492.938 | K36: 1500 | L36: 8 | N36: =IF(L36="","",L36-I36) -> 0 | O36: =IF(L36<>"",O35+L36/24,O35+I36/24) -> 45492.76 | Q36: =H36 -> 1500 | R36: =I36 -> 8 | U36: 250 | V36: =(G36-F36)/I36 -> -177.5 | W36: =(K36-K32)/(L36-M36) -> 177.5 | Y36: =ROUNDDOWN(0.085*$E$15*(G36-F36)/25.5,2) -> -4.73
A37: =A36+1 -> 18 | B37: СПО | C37: Шаблонирование спуск КНБК | E37: =E36 -> 245 | F37: 80 | G37: =G34 -> 1500 | H37: =H36 -> 1500 | I37: 7 | J37: =IF(I37<>"",J36+I37/24,"") -> 45493.229 | K37: 1500 | L37: 5.75 | N37: =IF(L37="","",L37-I37) -> -1.25 | O37: =IF(L37<>"",O36+L37/24,O36+I37/24) -> 45493 | Q37: =H37 -> 1500 | R37: =I37 -> 7
A38: =A37+1 -> 19 | B38: Циркуляция и Обработка БР | C38: Промывка на забое,продувка | E38: =E37 -> 245 | H38: =H37 -> 1500 | I38: 2 | J38: =IF(I38<>"",J37+I38/24,"") -> 45493.312 | K38: 1500 | L38: 2 | N38: =IF(L38="","",L38-I38) -> 0 | O38: =IF(L38<>"",O37+L38/24,O37+I38/24) -> 45493.083 | Q38: =H38 -> 1500 | R38: =I38 -> 2 | U38: 270 | V38: =(G38-F38)/I38 -> 0 | W38: =K38/(L38-M38) -> 750
A39: =A38+1 -> 20 | B39: СПО | C39: Подъём КНБК | E39: =E38 -> 245 | F39: =G37 -> 1500 | G39: 0 | H39: =H38 -> 1500 | I39: 7 | J39: =IF(I39<>"",J38+I39/24,"") -> 45493.604 | K39: 1500 | L39: 4.5 | N39: =IF(L39="","",L39-I39) -> -2.5 | O39: =IF(L39<>"",O38+L39/24,O38+I39/24) -> 45493.271 | Q39: =H39 -> 1500 | R39: =I39 -> 7
A40: =A39+1 -> 21 | B40: КНБК | C40: Разборка КНБК с телесистемой | E40: =E39 -> 245 | H40: =H39 -> 1500 | I40: 3 | J40: =IF(I40<>"",J39+I40/24,"") -> 45493.729 | K40: 1500 | L40: 3 | N40: =IF(L40="","",L40-I40) -> 0 | O40: =IF(L40<>"",O39+L40/24,O39+I40/24) -> 45493.396 | Q40: =H40 -> 1500 | R40: =I40 -> 3 | Y40: ч
A41: =A40+1 -> 22 | B41: Подготовительные работы | C41: ПЗР к спуску ОК 245мм | E41: =E40 -> 245 | H41: =H40 -> 1500 | I41: 1 | J41: =IF(I41<>"",J40+I41/24,"") -> 45493.771 | K41: 1500 | L41: 0.5 | N41: =IF(L41="","",L41-I41) -> -0.5 | O41: =IF(L41<>"",O40+L41/24,O40+I41/24) -> 45493.417 | Q41: =H41 -> 1500 | R41: =I41 -> 1 | U41: =60/(3.5)*11.3 -> 193.71429 | V41: =(G41-F41)/I41 -> 0 | W41: =K41/(L41-M41) -> 3000 | Y41: =(G41-F41)/U41 -> 0
...

Sheet Для Печати
A1: Сетевой график "Глубина-день"
B2: Компания | C2: ='Глубина-день'!C3 -> ООО "Газпромнефть-Хантос"
B3: Месторождение | C3: ='Глубина-день'!C4 -> Южно-Приобское
B4: Кустовая площадка | C4: ='Глубина-день'!C5 -> 112А.1
B5: Скважина № | C5: ='Глубина-день'!C6 -> 46626
B6: Руководитель направления | C6: ='Глубина-день'!C7 -> ГС
B7: Супервайзер АО "НИПЦ ГНТ" | C7: =IF('Глубина-день'!C8="","",'Глубина-день'!C8) -> Тырин Владимир Олегович
C8: =IF('Глубина-день'!C9="","",'Глубина-день'!C9)
C9: =IF('Глубина-день'!C10="","",'Глубина-день'!C10)
B10: Дата начала бурения | C10: =IF('глубина-день'!#ref!="","",'глубина-день'!#ref!) -> #VALUE!
A11: ='Глубина-день'!A17:E17 -> Операции | E11: ='Глубина-день'!F17:R17 -> #VALUE! | M11: ='Глубина-день'!K17:P17 -> 0
A12: # | B12: Операции | C12: Описание | D12: Секция | E12: Инт. 1 | F12: Инт. 2 | G12: Проходка | H12: Забой | I12: Время | J12: Дата окончания | K12: РГ | L12: БнБ | M12: Забой | N12: Время Факт | O12: Примечание
A13: =IF('Глубина-день'!A20="","",'Глубина-день'!A20) -> 1 | B13: =IF('Глубина-день'!B20="","",'Глубина-день'!B20) -> КНБК | C13: =IF('Глубина-день'!C20="","",'Глубина-день'!C20) -> Сборка роторной КНБК | D13: =IF('Глубина-день'!E20="","",'Глубина-день'!E20) -> 324 | E13: =IF('Глубина-день'!F20="","",'Глубина-день'!F20) -> 0 | F13: =IF('Глубина-день'!G20="","",'Глубина-день'!G20) | G13: =IF('глубина-день'!#ref!="","",'глубина-день'!#ref!) -> #VALUE! | H13: =IF('Глубина-день'!H20="","",'Глубина-день'!H20) -> 0 | I13: =IF('Глубина-день'!I20="","",'Глубина-день'!I20) -> 0.5 | J13: =IF('Глубина-день'!J20="","",'Глубина-день'!J20) -> 45489.229 | K13: =IF('Глубина-день'!R20="","",'Глубина-день'!R20) -> 0.5 | L13: =IF('глубина-день'!#ref!="","",'глубина-день'!#ref!) -> #VALUE!
A14: =IF('Глубина-день'!A21="","",'Глубина-день'!A21) -> 2 | B14: =IF('Глубина-день'!B21="","",'Глубина-день'!B21) -> Бурение | C14: =IF('Глубина-день'!C21="","",'Глубина-день'!C21) -> Бурение под направление | D14: =IF('Глубина-день'!E21="","",'Глубина-день'!E21) -> 324 | E14: =IF('Глубина-день'!F21="","",'Глубина-день'!F21) -> 0 | F14: =IF('Глубина-день'!G21="","",'Глубина-день'!G21) -> 80 | G14: =IF('глубина-день'!#ref!="","",'глубина-день'!#ref!) -> #VALUE! | H14: =IF('Глубина-день'!H21="","",'Глубина-день'!H21) -> 80 | I14: =IF('Глубина-день'!I21="","",'Глубина-день'!I21) -> 2 | J14: =IF('Глубина-день'!J21="","",'Глубина-день'!J21) -> 45489.312 | K14: =IF('Глубина-день'!R21="","",'Глубина-день'!R21) -> 2 | L14: =IF('глубина-день'!#ref!="","",'глубина-день'!#ref!) -> #VALUE!
A15: =IF('Глубина-день'!A22="","",'Глубина-день'!A22) -> 3 | B15: =IF('Глубина-день'!B22="","",'Глубина-день'!B22) -> Шаблонирование / проработка | C15: =IF('Глубина-день'!C22="","",'Глубина-день'!C22) -> Шаблонировка пробуренного интервала + промывка на забое+ подъем КНБК | D15: =IF('Глубина-день'!E22="","",'Глубина-день'!E22) -> 324 | E15: =IF('Глубина-день'!F22="","",'Глубина-день'!F22) -> 0 | F15: =IF('Глубина-день'!G22="","",'Глубина-день'!G22) -> 80 | G15: =IF('глубина-день'!#ref!="","",'глубина-день'!#ref!) -> #VALUE! | H15: =IF('Глубина-день'!H22="","",'Глубина-день'!H22) -> 80 | I15: =IF('Глубина-день'!I22="","",'Глубина-день'!I22) -> 1 | J15: =IF('Глубина-день'!J22="","",'Глубина-день'!J22) -> 45489.354 | K15: =IF('Глубина-день'!R22="","",'Глубина-день'!R22) -> 1 | L15: =IF('глубина-день'!#ref!="","",'глубина-день'!#ref!) -> #VALUE!
A16: =IF('Глубина-день'!A23="","",'Глубина-день'!A23) -> 4 | B16: =IF('Глубина-день'!B23="","",'Глубина-день'!B23) -> КНБК | C16: =IF('Глубина-день'!C23="","",'Глубина-день'!C23) -> Разборка КНБК | D16: =IF('Глубина-день'!E23="","",'Глубина-день'!E23) -> 324 | E16: =IF('Глубина-день'!F23="","",'Глубина-день'!F23) | F16: =IF('Глубина-день'!G23="","",'Глубина-день'!G23) | G16: =IF('глубина-день'!#ref!="","",'глубина-день'!#ref!) -> #VALUE! | H16: =IF('Глубина-день'!H23="","",'Глубина-день'!H23) -> 80 | I16: =IF('Глубина-день'!I23="","",'Глубина-день'!I23) -> 0.5 | J16: =IF('Глубина-день'!J23="","",'Глубина-день'!J23) -> 45489.375 | K16: =IF('Глубина-день'!R23="","",'Глубина-день'!R23) -> 0.5 | L16: =IF('глубина-день'!#ref!="","",'глубина-день'!#ref!) -> #VALUE!
A17: =IF('Глубина-день'!A24="","",'Глубина-день'!A24) -> 5 | B17: =IF('Глубина-день'!B24="","",'Глубина-день'!B24) -> Подготовительные работы | C17: =IF('Глубина-день'!C24="","",'Глубина-день'!C24) -> ПР к спуску направления 324мм | D17: =IF('Глубина-день'!E24="","",'Глубина-день'!E24) -> 324 | E17: =IF('Глубина-день'!F24="","",'Глубина-день'!F24) | F17: =IF('Глубина-день'!G24="","",'Глубина-день'!G24) | G17: =IF('глубина-день'!#ref!="","",'глубина-день'!#ref!) -> #VALUE! | H17: =IF('Глубина-день'!H24="","",'Глубина-день'!H24) -> 80 | I17: =IF('Глубина-день'!I24="","",'Глубина-день'!I24) -> 1 | J17: =IF('Глубина-день'!J24="","",'Глубина-день'!J24) -> 45489.417 | K17: =IF('Глубина-день'!R24="","",'Глубина-день'!R24) -> 1 | L17: =IF('глубина-день'!#ref!="","",'глубина-день'!#ref!) -> #VALUE!
A18: =IF('Глубина-день'!A25="","",'Глубина-день'!A25) -> 6 | B18: =IF('Глубина-день'!B25="","",'Глубина-день'!B25) -> Крепление | C18: =IF('Глубина-день'!C25="","",'Глубина-день'!C25) -> Спуск направления 324мм | D18: =IF('Глубина-день'!E25="","",'Глубина-день'!E25) -> 324 | E18: =IF('Глубина-день'!F25="","",'Глубина-день'!F25) -> 0 | F18: =IF('Глубина-день'!G25="","",'Глубина-день'!G25) -> 80 | G18: =IF('глубина-день'!#ref!="","",'глубина-день'!#ref!) -> #VALUE! | H18: =IF('Глубина-день'!H25="","",'Глубина-день'!H25) -> 80 | I18: =IF('Глубина-день'!I25="","",'Глубина-день'!I25) -> 2 | J18: =IF('Глубина-день'!J25="","",'Глубина-день'!J25) -> 45489.5 | K18: =IF('Глубина-день'!R25="","",'Глубина-день'!R25) -> 2 | L18: =IF('глубина-день'!#ref!="","",'глубина-день'!#ref!) -> #VALUE!
A19: =IF('Глубина-день'!A26="","",'Глубина-день'!A26) -> 7 | B19: =IF('Глубина-день'!B26="","",'Глубина-день'!B26) -> Циркуляция и Обработка БР | C19: =IF('Глубина-день'!C26="","",'Глубина-день'!C26) -> Промывка перед цементажем | D19: =IF('Глубина-день'!E26="","",'Глубина-день'!E26) -> 324 | E19: =IF('Глубина-день'!F26="","",'Глубина-день'!F26) | F19: =IF('Глубина-день'!G26="","",'Глубина-день'!G26) | G19: =IF('глубина-день'!#ref!="","",'глубина-день'!#ref!) -> #VALUE! | H19: =IF('Глубина-день'!H26="","",'Глубина-день'!H26) -> 80 | I19: =IF('Глубина-день'!I26="","",'Глубина-день'!I26) -> 0.5 | J19: =IF('Глубина-день'!J26="","",'Глубина-день'!J26) -> 45489.521 | K19: =IF('Глубина-день'!R26="","",'Глубина-день'!R26) -> 0.5 | L19: =IF('глубина-день'!#ref!="","",'глубина-день'!#ref!) -> #VALUE!
A20: =IF('Глубина-день'!A27="","",'Глубина-день'!A27) -> 8 | B20: =IF('Глубина-день'!B27="","",'Глубина-день'!B27) -> Крепление | C20: =IF('Глубина-день'!C27="","",'Глубина-день'!C27) -> Цементаж направления 324мм | D20: =IF('Глубина-день'!E27="","",'Глубина-день'!E27) -> 324 | E20: =IF('Глубина-день'!F27="","",'Глубина-день'!F27) | F20: =IF('Глубина-день'!G27="","",'Глубина-день'!G27) | G20: =IF('глубина-день'!#ref!="","",'глубина-день'!#ref!) -> #VALUE! | H20: =IF('Глубина-день'!H27="","",'Глубина-день'!H27) -> 80 | I20: =IF('Глубина-день'!I27="","",'Глубина-день'!I27) -> 1.5 | J20: =IF('Глубина-день'!J27="","",'Глубина-день'!J27) -> 45489.583 | K20: =IF('Глубина-день'!R27="","",'Глубина-день'!R27) -> 1.5 | L20: =IF('глубина-день'!#ref!="","",'глубина-день'!#ref!) -> #VALUE!
A21: =IF('глубина-день'!#ref!="","",'глубина-день'!#ref!) -> #VALUE! | B21: =IF('глубина-день'!#ref!="","",'глубина-день'!#ref!) -> #VALUE! | C21: =IF('глубина-день'!#ref!="","",'глубина-день'!#ref!) -> #VALUE! | D21: =IF('глубина-день'!#ref!="","",'глубина-день'!#ref!) -> #VALUE! | E21: =IF('глубина-день'!#ref!="","",'глубина-день'!#ref!) -> #VALUE! | F21: =IF('глубина-день'!#ref!="","",'глубина-день'!#ref!) -> #VALUE! | G21: =IF('глубина-день'!#ref!="","",'глубина-день'!#ref!) -> #VALUE! | H21: =IF('глубина-день'!#ref!="","",'глубина-день'!#ref!) -> #VALUE! | ... L21: =IF('глубина-день'!#ref!="","",'глубина-день'!#ref!) -> #VALUE!
A22: =IF('Глубина-день'!A30="","",'Глубина-день'!A30) -> 11 | B22: =IF('Глубина-день'!B30="","",'Глубина-день'!B30) -> КНБК | C22: =IF('Глубина-день'!C30="","",'Глубина-день'!C30) -> Сборка КНБК для бурения | D22: =IF('Глубина-день'!E30="","",'Глубина-день'!E30) -> 244.5 | E22: =IF('Глубина-день'!F30="","",'Глубина-день'!F30) | F22: =IF('Глубина-день'!G30="","",'Глубина-день'!G30) | G22: =IF('глубина-день'!#ref!="","",'глубина-день'!#ref!) -> #VALUE! | H22: =IF('Глубина-день'!H30="","",'Глубина-день'!H30) -> 80 | I22: =IF('Глубина-день'!I30="","",'Глубина-день'!I30) -> 3 | J22: =IF('Глубина-день'!J30="","",'Глубина-день'!J30) -> 45490.542 | K22: =IF('Глубина-день'!R30="","",'Глубина-день'!R30) -> 3 | L22: =IF('глубина-день'!#ref!="","",'глубина-день'!#ref!) -> #VALUE!
A23: =IF('Глубина-день'!A31="","",'Глубина-день'!A31) -> 12 | B23: =IF('Глубина-день'!B31="","",'Глубина-день'!B31) -> СПО | C23: =IF('Глубина-день'!C31="","",'Глубина-день'!C31) -> Cпуск КНБК со сборкой БИ с мостков | D23: =IF('Глубина-день'!E31="","",'Глубина-день'!E31) -> 244.5 | E23: =IF('Глубина-день'!F31="","",'Глубина-день'!F31) -> 0 | F23: =IF('Глубина-день'!G31="","",'Глубина-день'!G31) -> 80 | G23: =IF('глубина-день'!#ref!="","",'глубина-день'!#ref!) -> #VALUE! | H23: =IF('Глубина-день'!H31="","",'Глубина-день'!H31) -> 80 | I23: =IF('Глубина-день'!I31="","",'Глубина-день'!I31) -> 0.5 | J23: =IF('Глубина-день'!J31="","",'Глубина-день'!J31) -> 45490.562 | K23: =IF('Глубина-день'!R31="","",'Глубина-день'!R31) -> 0.5 | L23: =IF('глубина-день'!#ref!="","",'глубина-день'!#ref!) -> #VALUE!
A24: =IF('Глубина-день'!A32="","",'Глубина-день'!A32) -> 13 | B24: =IF('Глубина-день'!B32="","",'Глубина-день'!B32) -> Бурение | C24: =IF('Глубина-день'!C32="","",'Глубина-день'!C32) -> Разбурка оснастки (ЦКОД, цем.стакан, БК), замена раствора | D24: =IF('Глубина-день'!E32="","",'Глубина-день'!E32) -> 244.5 | E24: =IF('Глубина-день'!F32="","",'Глубина-день'!F32) -> 75 | F24: =IF('Глубина-день'!G32="","",'Глубина-день'!G32) -> 81 | G24: =IF('глубина-день'!#ref!="","",'глубина-день'!#ref!) -> #VALUE! | H24: =IF('Глубина-день'!H32="","",'Глубина-день'!H32) -> 81 | I24: =IF('Глубина-день'!I32="","",'Глубина-день'!I32) -> 1 | J24: =IF('Глубина-день'!J32="","",'Глубина-день'!J32) -> 45490.604 | K24: =IF('Глубина-день'!R32="","",'Глубина-день'!R32) -> 1 | L24: =IF('глубина-день'!#ref!="","",'глубина-день'!#ref!) -> #VALUE!
A25: =IF('Глубина-день'!A33="","",'Глубина-день'!A33) -> 14 | B25: =IF('Глубина-день'!B33="","",'Глубина-день'!B33) -> Вспомогательные работы | C25: =IF('Глубина-день'!C33="","",'Глубина-день'!C33) -> Чистка ЦСГО | D25: =IF('Глубина-день'!E33="","",'Глубина-день'!E33) -> 245 | E25: =IF('Глубина-день'!F33="","",'Глубина-день'!F33) | F25: =IF('Глубина-день'!G33="","",'Глубина-день'!G33) | G25: =IF('глубина-день'!#ref!="","",'глубина-день'!#ref!) -> #VALUE! | H25: =IF('Глубина-день'!H33="","",'Глубина-день'!H33) -> 81 | I25: =IF('Глубина-день'!I33="","",'Глубина-день'!I33) -> 1 | J25: =IF('Глубина-день'!J33="","",'Глубина-день'!J33) -> 45490.646 | K25: =IF('Глубина-день'!R33="","",'Глубина-день'!R33) -> 1 | L25: =IF('глубина-день'!#ref!="","",'глубина-день'!#ref!) -> #VALUE!
A26: =IF('Глубина-день'!A34="","",'Глубина-день'!A34) -> 15 | B26: =IF('Глубина-день'!B34="","",'Глубина-день'!B34) -> Бурение | C26: =IF('Глубина-день'!C34="","",'Глубина-день'!C34) -> Бурение под кондуктор (наращивание с мостков) | D26: =IF('Глубина-день'!E34="","",'Глубина-день'!E34) -> 245 | E26: =IF('Глубина-день'!F34="","",'Глубина-день'!F34) -> 81 | F26: =IF('Глубина-день'!G34="","",'Глубина-день'!G34) -> 1500 | G26: =IF('глубина-день'!#ref!="","",'глубина-день'!#ref!) -> #VALUE! | H26: =IF('Глубина-день'!H34="","",'Глубина-день'!H34) -> 1500 | I26: =IF('Глубина-день'!I34="","",'Глубина-день'!I34) -> 45 | J26: =IF('Глубина-день'!J34="","",'Глубина-день'!J34) -> 45492.521 | K26: =IF('Глубина-день'!R34="","",'Глубина-день'!R34) -> 45 | L26: =IF('глубина-день'!#ref!="","",'глубина-день'!#ref!) -> #VALUE!
A27: =IF('Глубина-день'!A35="","",'Глубина-день'!A35) -> 16 | B27: =IF('Глубина-день'!B35="","",'Глубина-день'!B35) -> Циркуляция и Обработка БР | C27: =IF('Глубина-день'!C35="","",'Глубина-день'!C35) -> Промывка на забое, продувка | D27: =IF('Глубина-день'!E35="","",'Глубина-день'!E35) -> 245 | E27: =IF('Глубина-день'!F35="","",'Глубина-день'!F35) | F27: =IF('Глубина-день'!G35="","",'Глубина-день'!G35) | G27: =IF('глубина-день'!#ref!="","",'глубина-день'!#ref!) -> #VALUE! | H27: =IF('Глубина-день'!H35="","",'Глубина-день'!H35) -> 1500 | I27: =IF('Глубина-день'!I35="","",'Глубина-день'!I35) -> 2 | J27: =IF('Глубина-день'!J35="","",'Глубина-день'!J35) -> 45492.604 | K27: =IF('Глубина-день'!R35="","",'Глубина-день'!R35) -> 2 | L27: =IF('глубина-день'!#ref!="","",'глубина-день'!#ref!) -> #VALUE!
A28: =IF('Глубина-день'!A36="","",'Глубина-день'!A36) -> 17 | B28: =IF('Глубина-день'!B36="","",'Глубина-день'!B36) -> СПО | C28: =IF('Глубина-день'!C36="","",'Глубина-день'!C36) -> Шаблонирование подъём КНБК | D28: =IF('Глубина-день'!E36="","",'Глубина-день'!E36) -> 245 | E28: =IF('Глубина-день'!F36="","",'Глубина-день'!F36) -> 1500 | F28: =IF('Глубина-день'!G36="","",'Глубина-день'!G36) -> 80 | G28: =IF('глубина-день'!#ref!="","",'глубина-день'!#ref!) -> #VALUE! | H28: =IF('Глубина-день'!H36="","",'Глубина-день'!H36) -> 1500 | I28: =IF('Глубина-день'!I36="","",'Глубина-день'!I36) -> 8 | J28: =IF('Глубина-день'!J36="","",'Глубина-день'!J36) -> 45492.938 | K28: =IF('Глубина-день'!R36="","",'Глубина-день'!R36) -> 8 | L28: =IF('глубина-день'!#ref!="","",'глубина-день'!#ref!) -> #VALUE!
A29: =IF('Глубина-день'!A37="","",'Глубина-день'!A37) -> 18 | B29: =IF('Глубина-день'!B37="","",'Глубина-день'!B37) -> СПО | C29: =IF('Глубина-день'!C37="","",'Глубина-день'!C37) -> Шаблонирование спуск КНБК | D29: =IF('Глубина-день'!E37="","",'Глубина-день'!E37) -> 245 | E29: =IF('Глубина-день'!F37="","",'Глубина-день'!F37) -> 80 | F29: =IF('Глубина-день'!G37="","",'Глубина-день'!G37) -> 1500 | G29: =IF('глубина-день'!#ref!="","",'глубина-день'!#ref!) -> #VALUE! | H29: =IF('Глубина-день'!H37="","",'Глубина-день'!H37) -> 1500 | I29: =IF('Глубина-день'!I37="","",'Глубина-день'!I37) -> 7 | J29: =IF('Глубина-день'!J37="","",'Глубина-день'!J37) -> 45493.229 | K29: =IF('Глубина-день'!R37="","",'Глубина-день'!R37) -> 7 | L29: =IF('глубина-день'!#ref!="","",'глубина-день'!#ref!) -> #VALUE!
A30: =IF('Глубина-день'!A38="","",'Глубина-день'!A38) -> 19 | B30: =IF('Глубина-день'!B38="","",'Глубина-день'!B38) -> Циркуляция и Обработка БР | C30: =IF('Глубина-день'!C38="","",'Глубина-день'!C38) -> Промывка на забое,продувка | D30: =IF('Глубина-день'!E38="","",'Глубина-день'!E38) -> 245 | E30: =IF('Глубина-день'!F38="","",'Глубина-день'!F38) | F30: =IF('Глубина-день'!G38="","",'Глубина-день'!G38) | G30: =IF('глубина-день'!#ref!="","",'глубина-день'!#ref!) -> #VALUE! | H30: =IF('Глубина-день'!H38="","",'Глубина-день'!H38) -> 1500 | I30: =IF('Глубина-день'!I38="","",'Глубина-день'!I38) -> 2 | J30: =IF('Глубина-день'!J38="","",'Глубина-день'!J38) -> 45493.312 | K30: =IF('Глубина-день'!R38="","",'Глубина-день'!R38) -> 2 | L30: =IF('глубина-день'!#ref!="","",'глубина-день'!#ref!) -> #VALUE!
A31: =IF('Глубина-день'!A39="","",'Глубина-день'!A39) -> 20 | B31: =IF('Глубина-день'!B39="","",'Глубина-день'!B39) -> СПО | C31: =IF('Глубина-день'!C39="","",'Глубина-день'!C39) -> Подъём КНБК | D31: =IF('Глубина-день'!E39="","",'Глубина-день'!E39) -> 245 | E31: =IF('Глубина-день'!F39="","",'Глубина-день'!F39) -> 1500 | F31: =IF('Глубина-день'!G39="","",'Глубина-день'!G39) -> 0 | G31: =IF('глубина-день'!#ref!="","",'глубина-день'!#ref!) -> #VALUE! | H31: =IF('Глубина-день'!H39="","",'Глубина-день'!H39) -> 1500 | I31: =IF('Глубина-день'!I39="","",'Глубина-день'!I39) -> 7 | J31: =IF('Глубина-день'!J39="","",'Глубина-день'!J39) -> 45493.604 | K31: =IF('Глубина-день'!R39="","",'Глубина-день'!R39) -> 7 | L31: =IF('глубина-день'!#ref!="","",'глубина-день'!#ref!) -> #VALUE!
A32: =IF('Глубина-день'!A40="","",'Глубина-день'!A40) -> 21 | B32: =IF('Глубина-день'!B40="","",'Глубина-день'!B40) -> КНБК | C32: =IF('Глубина-день'!C40="","",'Глубина-день'!C40) -> Разборка КНБК с телесистемой | D32: =IF('Глубина-день'!E40="","",'Глубина-день'!E40) -> 245 | E32: =IF('Глубина-день'!F40="","",'Глубина-день'!F40) | F32: =IF('Глубина-день'!G40="","",'Глубина-день'!G40) | G32: =IF('глубина-день'!#ref!="","",'глубина-день'!#ref!) -> #VALUE! | H32: =IF('Глубина-день'!H40="","",'Глубина-день'!H40) -> 1500 | I32: =IF('Глубина-день'!I40="","",'Глубина-день'!I40) -> 3 | J32: =IF('Глубина-день'!J40="","",'Глубина-день'!J40) -> 45493.729 | K32: =IF('Глубина-день'!R40="","",'Глубина-день'!R40) -> 3 | L32: =IF('глубина-день'!#ref!="","",'глубина-день'!#ref!) -> #VALUE!
A33: =IF('Глубина-день'!A41="","",'Глубина-день'!A41) -> 22 | B33: =IF('Глубина-день'!B41="","",'Глубина-день'!B41) -> Подготовительные работы | C33: =IF('Глубина-день'!C41="","",'Глубина-день'!C41) -> ПЗР к спуску ОК 245мм | D33: =IF('Глубина-день'!E41="","",'Глубина-день'!E41) -> 245 | E33: =IF('Глубина-день'!F41="","",'Глубина-день'!F41) | F33: =IF('Глубина-день'!G41="","",'Глубина-день'!G41) | G33: =IF('глубина-день'!#ref!="","",'глубина-день'!#ref!) -> #VALUE! | H33: =IF('Глубина-день'!H41="","",'Глубина-день'!H41) -> 1500 | I33: =IF('Глубина-день'!I41="","",'Глубина-день'!I41) -> 1 | J33: =IF('Глубина-день'!J41="","",'Глубина-день'!J41) -> 45493.771 | K33: =IF('Глубина-день'!R41="","",'Глубина-день'!R41) -> 1 | L33: =IF('глубина-день'!#ref!="","",'глубина-день'!#ref!) -> #VALUE!
... A35: =IF('Глубина-день'!A43="","",'Глубина-день'!A43) -> 24 | B35: =IF('Глубина-день'!B43="","",'Глубина-день'!B43) -> Циркуляция и Обработка БР | C35: =IF('Глубина-день'!C43="","",'Глубина-день'!C43) -> Промывка перед цементажем | D35: =IF('Глубина-день'!E43="","",'Глубина-день'!E43) -> 245 | E35: =IF('Глубина-день'!F43="","",'Глубина-день'!F43) | F35: =IF('Глубина-день'!G43="","",'Глубина-день'!G43) | G35: =IF('глубина-день'!#ref!="","",'глубина-день'!#ref!) -> #VALUE! | H35: =IF('Глубина-день'!H43="","",'Глубина-день'!H43) -> 1500 | I35: =IF('Глубина-день'!I43="","",'Глубина-день'!I43) -> 2 | J35: =IF('Глубина-день'!J43="","",'Глубина-день'!J43) -> 45494.396 | K35: =IF('Глубина-день'!R43="","",'Глубина-день'!R43) -> 2 | L35: =IF('глубина-день'!#ref!="","",'глубина-день'!#ref!) -> #VALUE!
A36: =IF('Глубина-день'!A45="","",'Глубина-день'!A45) -> 26 | B36: =IF('Глубина-день'!B45="","",'Глубина-день'!B45) -> Вспомогательные работы | C36: =IF('Глубина-день'!C45="","",'Глубина-день'!C45) -> Монтаж ОУС,Вывоз БР | D36: =IF('Глубина-день'!E45="","",'Глубина-день'!E45) -> 245 | E36: =IF('Глубина-день'!F45="","",'Глубина-день'!F45) | F36: =IF('Глубина-день'!G45="","",'Глубина-день'!G45) | G36: =IF('глубина-день'!#ref!="","",'глубина-день'!#ref!) -> #VALUE! | H36: =IF('Глубина-день'!H45="","",'Глубина-день'!H45) -> 1500 | I36: =IF('Глубина-день'!I45="","",'Глубина-день'!I45) -> 2 | J36: =IF('Глубина-день'!J45="","",'Глубина-день'!J45) -> 45494.604 | K36: =IF('Глубина-день'!R45="","",'Глубина-день'!R45) -> 2 | L36: =IF('глубина-день'!#ref!="","",'глубина-день'!#ref!) -> #VALUE!
A37: =IF('глубина-день'!#ref!="","",'глубина-день'!#ref!) -> #VALUE! | B37: =IF('глубина-день'!#ref!="","",'глубина-день'!#ref!) -> #VALUE! | C37: =IF('глубина-день'!#ref!="","",'глубина-день'!#ref!) -> #VALUE! | D37: =IF('глубина-день'!#ref!="","",'глубина-день'!#ref!) -> #VALUE! | E37: =IF('глубина-день'!#ref!="","",'глубина-день'!#ref!) -> #VALUE! | F37: =IF('глубина-день'!#ref!="","",'глубина-день'!#ref!) -> #VALUE! | G37: =IF('глубина-день'!#ref!="","",'глубина-день'!#ref!) -> #VALUE! | H37: =IF('глубина-день'!#ref!="","",'глубина-день'!#ref!) -> #VALUE! | ... L37: =IF('глубина-день'!#ref!="","",'глубина-день'!#ref!) -> #VALUE!
A38: =IF('глубина-день'!#ref!="","",'глубина-день'!#ref!) -> #VALUE! | B38: =IF('глубина-день'!#ref!="","",'глубина-день'!#ref!) -> #VALUE! | C38: =IF('глубина-день'!#ref!="","",'глубина-день'!#ref!) -> #VALUE! | D38: =IF('глубина-день'!#ref!="","",'глубина-день'!#ref!) -> #VALUE! | E38: =IF('глубина-день'!#ref!="","",'глубина-день'!#ref!) -> #VALUE! | F38: =IF('глубина-день'!#ref!="","",'глубина-день'!#ref!) -> #VALUE! | G38: =IF('глубина-день'!#ref!="","",'глубина-день'!#ref!) -> #VALUE! | H38: =IF('глубина-день'!#ref!="","",'глубина-день'!#ref!) -> #VALUE! | ... L38: =IF('глубина-день'!#ref!="","",'глубина-день'!#ref!) -> #VALUE!
A39: =IF('Глубина-день'!A46="","",'Глубина-день'!A46) -> 27 | B39: =IF('Глубина-день'!B46="","",'Глубина-день'!B46) -> Вспомогательные работы | C39: =IF('Глубина-день'!C46="","",'Глубина-день'!C46) -> Монтаж ПВО, монтаж разрезной воронки и устьевого желоба | D39: =IF('Глубина-день'!E46="","",'Глубина-день'!E46) -> 245 | E39: =IF('Глубина-день'!F46="","",'Глубина-день'!F46) | F39: =IF('Глубина-день'!G46="","",'Глубина-день'!G46) | G39: =IF('глубина-день'!#ref!="","",'глубина-день'!#ref!) -> #VALUE! | H39: =IF('Глубина-день'!H46="","",'Глубина-день'!H46) -> 1500 | I39: =IF('Глубина-день'!I46="","",'Глубина-день'!I46) -> 6 | J39: =IF('Глубина-день'!J46="","",'Глубина-день'!J46) -> 45494.854 | K39: =IF('Глубина-день'!R46="","",'Глубина-день'!R46) -> 6 | L39: =IF('глубина-день'!#ref!="","",'глубина-день'!#ref!) -> #VALUE!
A40: =IF('глубина-день'!#ref!="","",'глубина-день'!#ref!) -> #VALUE! | B40: =IF('глубина-день'!#ref!="","",'глубина-день'!#ref!) -> #VALUE! | C40: =IF('глубина-день'!#ref!="","",'глубина-день'!#ref!) -> #VALUE! | D40: =IF('глубина-день'!#ref!="","",'глубина-день'!#ref!) -> #VALUE! | E40: =IF('глубина-день'!#ref!="","",'глубина-день'!#ref!) -> #VALUE! | F40: =IF('глубина-день'!#ref!="","",'глубина-день'!#ref!) -> #VALUE! | G40: =IF('глубина-день'!#ref!="","",'глубина-день'!#ref!) -> #VALUE! | H40: =IF('глубина-день'!#ref!="","",'глубина-день'!#ref!) -> #VALUE! | ... L40: =IF('глубина-день'!#ref!="","",'глубина-день'!#ref!) -> #VALUE!
A41: =IF('глубина-день'!#ref!="","",'глубина-день'!#ref!) -> #VALUE! | B41: =IF('глубина-день'!#ref!="","",'глубина-день'!#ref!) -> #VALUE! | C41: =IF('глубина-день'!#ref!="","",'глубина-день'!#ref!) -> #VALUE! | D41: =IF('глубина-день'!#ref!="","",'глубина-день'!#ref!) -> #VALUE! | E41: =IF('глубина-день'!#ref!="","",'глубина-день'!#ref!) -> #VALUE! | F41: =IF('глубина-день'!#ref!="","",'глубина-день'!#ref!) -> #VALUE! | G41: =IF('глубина-день'!#ref!="","",'глубина-день'!#ref!) -> #VALUE! | H41: =IF('глубина-день'!#ref!="","",'глубина-день'!#ref!) -> #VALUE! | ... L41: =IF('глубина-день'!#ref!="","",'глубина-день'!#ref!) -> #VALUE!
...

Sheet Графики
B2: Месторождение | C2: ='Глубина-день'!C4 -> Южно-Приобское | E2: План, сут* | G2: ='Глубина-день'!N7 -> 26.8625 | I2: Скорость бурения, сут/1000м | K2: План | M2: ='Глубина-день'!N10 -> 6.0378737 | O2: Начало бурения | Q2: ='Глубина-день'!N3 -> 45489.208
B3: Кустовая площадка | C3: ='Глубина-день'!C5 -> 112А.1 | E3: Факт/прогноз, сут | G3: ='Глубина-день'!N8 -> 27.166667 | K3: Факт/Прогноз | M3: ='Глубина-день'!N11 -> 6.1062411 | O3: Прогноз окончания бурения | Q3: ='Глубина-день'!N5 -> 45516.375
B4: Скважина № | C4: ='Глубина-день'!C6 -> 46626 | E4: Отклон.от плана, сут. | G4: ='Глубина-день'!N13 -> 0.30416667 | O4: Дата Бур.Подр.
Y7: Забой | Z7: ='Глубина-день'!K7 -> План, сут* | AB7: Забой | AC7: Факт/прогноз, сут | AE7: ='Глубина-день'!K9 -> БП, сут
Z8: Время | AA8: Суммарное | AC8: Время | AD8: Суммарное | AE8: Время | AF8: Суммарное
X9: ='Глубина-день'!A20 -> 1 | Y9: ='Глубина-день'!H20 -> 0 | Z9: ='Глубина-день'!I20 -> 0.5 | AA9: =Z9/24 -> 0.020833333 | AB9: ='Глубина-день'!K20 -> 0 | AC9: ='Глубина-день'!L20 -> 0.5 | AD9: =AC9/24 -> 0.020833333 | AE9: ='Глубина-день'!R20 -> 0.5 | AF9: =AE9/24 -> 0.020833333
X10: ='Глубина-день'!A21 -> 2 | Y10: ='Глубина-день'!H21 -> 80 | Z10: ='Глубина-день'!I21 -> 2 | AA10: =Z10/24+AA9 -> 0.10416667 | AB10: ='Глубина-день'!K21 -> 80 | AC10: ='Глубина-день'!L21 -> 2 | AD10: =AC10/24+AD9 -> 0.10416667 | AE10: ='Глубина-день'!R21 -> 2 | AF10: =AE10/24+AF9 -> 0.10416667
X11: ='Глубина-день'!A22 -> 3 | Y11: ='Глубина-день'!H22 -> 80 | Z11: ='Глубина-день'!I22 -> 1 | AA11: =Z11/24+AA10 -> 0.14583333 | AB11: ='Глубина-день'!K22 -> 80 | AC11: ='Глубина-день'!L22 -> 1 | AD11: =AC11/24+AD10 -> 0.14583333 | AE11: ='Глубина-день'!R22 -> 1 | AF11: =AE11/24+AF10 -> 0.14583333
X12: ='Глубина-день'!A23 -> 4 | Y12: ='Глубина-день'!H23 -> 80 | Z12: ='Глубина-день'!I23 -> 0.5 | AA12: =Z12/24+AA11 -> 0.16666667 | AB12: ='Глубина-день'!K23 -> 80 | AC12: ='Глубина-день'!L23 -> 0.5 | AD12: =AC12/24+AD11 -> 0.16666667 | AE12: ='Глубина-день'!R23 -> 0.5 | AF12: =AE12/24+AF11 -> 0.16666667
X13: ='Глубина-день'!A24 -> 5 | Y13: ='Глубина-день'!H24 -> 80 | Z13: ='Глубина-день'!I24 -> 1 | AA13: =Z13/24+AA12 -> 0.20833333 | AB13: ='Глубина-день'!K24 -> 80 | AC13: ='Глубина-день'!L24 -> 1 | AD13: =AC13/24+AD12 -> 0.20833333 | AE13: ='Глубина-день'!R24 -> 1 | AF13: =AE13/24+AF12 -> 0.20833333
X14: ='Глубина-день'!A25 -> 6 | Y14: ='Глубина-день'!H25 -> 80 | Z14: ='Глубина-день'!I25 -> 2 | AA14: =Z14/24+AA13 -> 0.29166667 | AB14: ='Глубина-день'!K25 -> 80 | AC14: ='Глубина-день'!L25 -> 2 | AD14: =AC14/24+AD13 -> 0.29166667 | AE14: ='Глубина-день'!R25 -> 2 | AF14: =AE14/24+AF13 -> 0.29166667
X15: ='Глубина-день'!A26 -> 7 | Y15: ='Глубина-день'!H26 -> 80 | Z15: ='Глубина-день'!I26 -> 0.5 | AA15: =Z15/24+AA14 -> 0.3125 | AB15: ='Глубина-день'!K26 -> 80 | AC15: ='Глубина-день'!L26 -> 0.5 | AD15: =AC15/24+AD14 -> 0.3125 | AE15: ='Глубина-день'!R26 -> 0.5 | AF15: =AE15/24+AF14 -> 0.3125
X16: ='Глубина-день'!A27 -> 8 | Y16: ='Глубина-день'!H27 -> 80 | Z16: ='Глубина-день'!I27 -> 1.5 | AA16: =Z16/24+AA15 -> 0.375 | AB16: ='Глубина-день'!K27 -> 80 | AC16: ='Глубина-день'!L27 -> 1.5 | AD16: =AC16/24+AD15 -> 0.375 | AE16: ='Глубина-день'!R27 -> 1.5 | AF16: =AE16/24+AF15 -> 0.375
X17: ='Глубина-день'!A28 -> 9 | Y17: ='Глубина-день'!H28 -> 80 | Z17: ='Глубина-день'!I28 -> 8 | AA17: =Z17/24+AA16 -> 0.70833333 | AB17: ='Глубина-день'!K28 -> 80 | AC17: ='Глубина-день'!L28 -> 8 | AD17: =AC17/24+AD16 -> 0.70833333 | AE17: ='Глубина-день'!R28 -> 8 | AF17: =AE17/24+AF16 -> 0.70833333
X18: ='Глубина-день'!A29 -> 10 | Y18: ='Глубина-день'!H29 -> 80 | Z18: ='Глубина-день'!I29 -> 12 | AA18: =Z18/24+AA17 -> 1.2083333 | AB18: ='Глубина-день'!K29 -> 80 | AC18: ='Глубина-день'!L29 -> 9 | AD18: =AC18/24+AD17 -> 1.0833333 | AE18: ='Глубина-день'!R29 -> 12 | AF18: =AE18/24+AF17 -> 1.2083333
X19: ='Глубина-день'!A30 -> 11 | Y19: ='Глубина-день'!H30 -> 80 | Z19: ='Глубина-день'!I30 -> 3 | AA19: =Z19/24+AA18 -> 1.3333333 | AB19: ='Глубина-день'!K30 -> 80 | AC19: ='Глубина-день'!L30 -> 2.5 | AD19: =AC19/24+AD18 -> 1.1875 | AE19: ='Глубина-день'!R30 -> 3 | AF19: =AE19/24+AF18 -> 1.3333333
X20: ='Глубина-день'!A31 -> 12 | Y20: ='Глубина-день'!H31 -> 80 | Z20: ='Глубина-день'!I31 -> 0.5 | AA20: =Z20/24+AA19 -> 1.3541667 | AB20: ='Глубина-день'!K31 -> 80 | AC20: ='Глубина-день'!L31 -> 0.25 | AD20: =AC20/24+AD19 -> 1.1979167 | AE20: ='Глубина-день'!R31 -> 0.5 | AF20: =AE20/24+AF19 -> 1.3541667
X21: ='Глубина-день'!A32 -> 13 | Y21: ='Глубина-день'!H32 -> 81 | Z21: ='Глубина-день'!I32 -> 1 | AA21: =Z21/24+AA20 -> 1.3958333 | AB21: ='Глубина-день'!K32 -> 80 | AC21: ='Глубина-день'!L32 -> 1 | AD21: =AC21/24+AD20 -> 1.2395833 | AE21: ='Глубина-день'!R32 -> 1 | AF21: =AE21/24+AF20 -> 1.3958333
... X78: ='Глубина-день'!A89 -> 70 | Y78: ='Глубина-день'!H89 -> 4449 | Z78: ='Глубина-день'!I89 -> 30.7 | AA78: =Z78/24+AA77 -> 26.8625 | AB78: ='Глубина-день'!K89 -> 0 | AC78: ='Глубина-день'!L89 -> 0 | AD78: =AC78/24+AD77 -> 21.791667 | AE78: ='Глубина-день'!R89 -> 30.7 | AF78: =AE78/24+AF77 -> 26.8625

Sheet реестр НПВ
A1: № НПВ | B1: Год | C1: Месяц | D1: Дата начала НПВ | E1: Дата окончания НПВ | F1: № скв | G1: № куста | H1: М-е | I1: Вид НПВ | J1: Классификация | K1: Расшифровка НПВ | L1: Виновная сторона | M1: НПВ, Простой, час
A3: 1
A4: 2
A5: 3
A6: 4
A7: 5
A8: 6
A9: 7
A10: 8
A11: 9
A12: 10
A13: 11
A14: 12
... A46: 44
L47: Общее НПВ по скв | M47: =SUM(M3:M43) -> 0
K49: Распределение НПВ по типам
K50: распределение НПВ по типам | L50: Аварии | M50: =SUMIFS($M$3:$M$46,$J$3:$J$46,L50) -> 0
L51: Осложнения | M51: =SUMIFS($M$3:$M$46,$J$3:$J$46,L51) -> 0
L52: Геологические осложнения | M52: =SUMIFS($M$3:$M$46,$J$3:$J$46,L52) -> 0
L53: Ликв.брака | M53: =SUMIFS($M$3:$M$46,$J$3:$J$46,L53) -> 0
L54: Простои | M54: =SUMIFS($M$3:$M$46,$J$3:$J$46,L54) -> 0
L55: Простои метео | M55: =SUMIFS($M$3:$M$46,$J$3:$J$46,L55) -> 0
L56: Ремонт ББ | M56: =SUMIFS($M$3:$M$46,$J$3:$J$46,L56) -> 0
L57: НПВ 1 | M57: =SUMIFS($M$3:$M$46,$J$3:$J$46,L57) -> 0
L58: НПВ 2 | M58: =SUMIFS($M$3:$M$46,$J$3:$J$46,L58) -> 0
L59: итого | M59: =SUM(M50:M58) -> 0
K61: Распределение НПВ по ПО
K62: распределение НПВ по ПО (можно менять нименования) | L62: ООО "ЮСК" | M62: =SUMIFS($M$3:$M$46,$L$3:$L$46,L62) -> 0
L63: НФ ООО "БКЕ" | M63: =SUMIFS($M$3:$M$46,$L$3:$L$46,L63) -> 0
L64: ООО "ССР" | M64: =SUMIFS($M$3:$M$46,$L$3:$L$46,L64) -> 0
L65: ООО "НПП "Буринтех" | M65: =SUMIFS($M$3:$M$46,$L$3:$L$46,L65) -> 0
L66: ООО "НПП "Буринтех" | M66: =SUMIFS($M$3:$M$46,$L$3:$L$46,L66) -> 0
L67: ООО "Бренд Фактор" | M67: =SUMIFS($M$3:$M$46,$L$3:$L$46,L67) -> 0
L68: ООО "НОРД-СЕРВИС" | M68: =SUMIFS($M$3:$M$46,$L$3:$L$46,L68) -> 0
L69: ООО "Зенит-Сервис" | M69: =SUMIFS($M$3:$M$46,$L$3:$L$46,L69) -> 0
L70: ПО 1 | M70: =SUMIFS($M$3:$M$46,$L$3:$L$46,L70) -> 0
L71: ПО 2 | M71: =SUMIFS($M$3:$M$46,$L$3:$L$46,L71) -> 0
L72: ПО 3 | M72: =SUMIFS($M$3:$M$46,$L$3:$L$46,L72) -> 0
L73: ПО 4 | M73: =SUMIFS($M$3:$M$46,$L$3:$L$46,L73) -> 0
L74: ГПНХ | M74: =SUMIFS($M$3:$M$46,$L$3:$L$46,L74) -> 0
...

Sheet Нормы
B2: Вид операции | C2: нормы
B3: опрессовка плашек, ПУГ | C3: 1.5
B4: Спуск 324 мм направления одной трубы | C4: 0.33
B6: Спуск инструмента (одной свечи), БУ 2900/200 ЭПКБМ-3, БУ 3000 ЭУК-1М, грузоподъемность 200 т, ВСП | C6: 0.085 | D6: Вывод из-за пальца, наворот, спуск свечи, подъем пустого блока.
B7: Спуск инструмента (одной свечи), БУ 2900/200 ЭПКБМ-3, БУ 3000 ЭУК-1М, грузоподъемность 200 т, без ВСП | C7: 0.08 | D7: Вывод из-за пальца, наворот, спуск свечи, подъем пустого блока.
B8: Спуск 245 мм кондуктора (одной трубы) | C8: 0.088
B10: Подъем инструмента (одной свечи), БУ 2900/200 ЭПКБМ-3, БУ 3000 ЭУК-1М, грузоподъемность 200 т, ВСП | C10: 0.089 | D10: Подъем свечи, отворот, установка за палец, спуск пустого блока.
B12: Подъем инструмента (одной свечи), БУ 2900/200 ЭПКБМ-3, БУ 3000 ЭУК-1М, грузоподъемность 200 т, без ВСП | C12: 0.084 | D12: Подъем свечи, отворот, установка за палец, спуск пустого блока.
B14: Сборка АМАК, АМК-Горизонт | C14: 1.92
B16: Спуск , подъем с записью АМАК, АМК-Горизонт | C16: 1.15 | D16: На 100м.
B18: Разборка АМАК, АМК-Горизонт, считывание данных | C18: 1.5
B20: Разборка и выброс 127 и 147 мм инструмента на мостки при подъеме 1 трубка | C20: 0.075 | D20: При выбросе инструмента на мостки из-за пальца учитывать время на спуск свечи ниже стола ротора по нормам спуска.
B21: Разборка и выброс 102 мм инструмента на мостки при подъеме 1 трубка | C21: 0.075
B22: Разборка и выброс 89 мм инструмента на мостки при подъеме 1 трубка | C22: 0.075
B23: Спуск 146 мм, 168 мм ,178 мм эксплуатационной колонны, 1 труба | C23: 0.07
B25: Сборка и спуск 114 мм хвостовика, 1 труба | C25: 0.093 | D25: Спуск хвостовика на транспортной колонне рассчитывается как спуск инструмента.
B27: Сборка с мостков и спуск 127 и 147 мм инструмента (1 трубы) | C27: 0.065 | D27: В случае применения нового комплекта БИ или БИ после проведения ремонта применяется дополнительно 0,04ч. для приработки БИ.
B28: Сборка с мостков и спуск 102 мм инструмента (1 трубы) | C28: 0.065
B29: Сборка с мостков и спуск 89 мм инструмента (1 трубы) | C29: 0.065
