Workbook

Sheet Глубина-день
A1: Сетевой график "Глубина-день"
B2: Определение | D2: Конструкция скважины | K2: Начальные и прогнозные параметры
B3: Компания | C3: ООО "Газпромнефть-Хантос" | D3: Проект | E3: Забой | K3: Начало бурения | N3: 45499.625
B4: Месторождение | C4: Южно-Приобское | D4: Секция | E4: План | H4: Факт | I4: св, шт | J4: ОК, шт | K4: План окончания бурения | N4: =J82 -> 45526.438
B5: Кустовая площадка | C5: 134В.1 ЮПМ | D5: 245 | E5: 80 | H5: 80 | J5: =ROUNDUP((E5-5)/11.3,0) -> 7 | K5: Факт/прогноз | N5: =O82 -> 45517.188
B6: Скважина № | C6: 43820 | D6: 178 | E6: 2543.15 | H6: 2543.31 | I6: =ROUNDUP((E6-E5)/25.5,0) -> 97 | J6: =ROUNDUP((E6-E5-5)/11.3,0) -> 218 | K6: План для бонуса | N6: =N3+R84 -> 45527.778
B7: Тип скважины | C7: 2КК, ГС без ПС | D7: Т1 | E7: 3160 | I7: =ROUNDUP((E7-E6)/25.5,0) -> 25 | J7: =ROUNDUP((E7-E6-5)/11.3,0) -> 55 | K7: =H17 -> План | N7: =I84 -> 28.153125
B8: Руководитель направления | C8: Богомягков В.А. | D8: 114 | E8: 4660 | I8: =ROUNDUP((E8-E7)/25.5,0) -> 59 | J8: =ROUNDUP((E8-E7-5)/11.3,0) -> 133 | K8: Факт/прогноз, сут | N8: =N5-N3 -> 17.5625
B9: Супервайзера ООО "КОМТЭК" | K9: =Q17 -> План для бонуса | N9: =N6-N3 -> 28.153125
D10: Длина ГС | E10: =E8-E7 -> 1500 | H10: =H8-H7 -> 0 | K10: Скорость бурения, сут/1000м | L10: План | N10: =N7/E13*1000 -> 6.0414431
D11: Пилот №1/точка срезки/Длина | G11: =E11-F11 -> 0 | J11: 0 | L11: Факт+Прогноз | N11: =N8/E13*1000 -> 3.7687768
D12: Пилот №2/точка срезки/Длина | G12: =E12-F12 -> 0 | J12: 0 | L12: План для бонуса | N12: =N9/E13*1000 -> 6.0414431
D13: Проходка | E13: =E8+G11+G12 -> 4660 | K13: Отклон.от плана, сут. | N13: =N5-N4 -> -9.25
D14: Индекс сложности | K14: Прогноз % времени на ТО БУ | N14: ='реестр НПВ'!M56/('Глубина-день'!N8*24-'реестр НПВ'!M63) -> 0
K15: *Плановое время учитывает 5% времени на ТО БУ
A17: Операции | H17: План | K17: Факт | Q17: План для бонуса | S17: Мероприятия
A18: # | B18: Операции | C18: Описание | E18: ОК | F18: Интервал | H18: Забой, м | I18: Время | J18: Окончание | K18: Забой, м | L18: Время Факт, ч | M18: НПВ, ч | N18: Откл | O18: Окончание | P18: Примечание | Q18: Забой, м | R18: Время | S18: Описание
F19: от | G19: до | O19: Факт/Прогноз
A20: 1 | B20: КНБК | C20: Сборка КНБК | E20: 245 | F20: 0 | H20: =G20 -> 0 | I20: 0.5 | J20: =N3+I20/24 -> 45499.646 | K20: 0 | L20: 0.25 | N20: =IF(L20="","",L20-I20) -> -0.25 | O20: =IF(L20<>"",N3+L20/24,N3+I20/24) -> 45499.635 | Q20: 0 | R20: 0.5
A21: =A20+1 -> 2 | B21: Бурение | C21: Бурение под направление | E21: 245 | F21: =F20 -> 0 | G21: =E5 -> 80 | H21: =G21 -> 80 | I21: 2 | J21: =IF(I21<>"",J20+I21/24,"") -> 45499.729 | K21: 80 | L21: 1 | N21: =IF(L21="","",L21-I21) -> -1 | O21: =IF(L21<>"",O20+L21/24,O20+I21/24) -> 45499.677 | Q21: 80 | R21: 2
A22: 3 | B22: Шаблонирование / проработка | C22: Шаблонирование перед спуском | E22: 245 | F22: =F21 -> 0 | G22: =G21 -> 80 | H22: =H21 -> 80 | I22: 1 | J22: =IF(I22<>"",J21+I22/24,"") -> 45499.771 | K22: 80 | L22: 0.5 | N22: =IF(L22="","",L22-I22) -> -0.5 | O22: =IF(L22<>"",O21+L22/24,O21+I22/24) -> 45499.698 | Q22: 80 | R22: 1
A23: =A22+1 -> 4 | B23: КНБК | C23: Разборка КНБК | E23: 245 | H23: =H22 -> 80 | I23: 0.5 | J23: =IF(I23<>"",J22+I23/24,"") -> 45499.792 | K23: 80 | L23: 0.5 | N23: =IF(L23="","",L23-I23) -> 0 | O23: =IF(L23<>"",O22+L23/24,O22+I23/24) -> 45499.719 | Q23: 80 | R23: 0.5
A24: 5 | B24: Подготовительные работы | C24: ПР к спуску направления 245 мм | E24: 245 | H24: =H23 -> 80 | I24: 0.5 | J24: =IF(I24<>"",J23+I24/24,"") -> 45499.812 | K24: 80 | L24: 0.25 | N24: =IF(L24="","",L24-I24) -> -0.25 | O24: =IF(L24<>"",O23+L24/24,O23+I24/24) -> 45499.729 | Q24: 80 | R24: 0.5
A25: 6 | B25: Крепление | C25: Спуск направления | E25: 245 | F25: =F20 -> 0 | G25: 80 | H25: =H24 -> 80 | I25: 2 | J25: =IF(I25<>"",J24+I25/24,"") -> 45499.896 | K25: 80 | L25: 1.25 | N25: =IF(L25="","",L25-I25) -> -0.75 | O25: =IF(L25<>"",O24+L25/24,O24+I25/24) -> 45499.781 | Q25: 80 | R25: 2
A26: 7 | B26: Циркуляция и Обработка БР | C26: Промывка перед цементажем | E26: 245 | H26: =H25 -> 80 | I26: 0.5 | J26: =IF(I26<>"",J25+I26/24,"") -> 45499.917 | K26: 80 | L26: 0.25 | N26: =IF(L26="","",L26-I26) -> -0.25 | O26: =IF(L26<>"",O25+L26/24,O25+I26/24) -> 45499.792 | Q26: 80 | R26: 0.5
A27: 8 | B27: Крепление | C27: Цементаж направления 245мм | E27: 245 | H27: =H26 -> 80 | I27: 1.5 | J27: =IF(I27<>"",J26+I27/24,"") -> 45499.979 | K27: 80 | L27: 1 | N27: =IF(L27="","",L27-I27) -> -0.5 | O27: =IF(L27<>"",O26+L27/24,O26+I27/24) -> 45499.833 | Q27: 80 | R27: 1.5
A28: 9 | B28: Крепление | C28: ОЗЦ Вывоз БР после бурения направления, Заготовка БР (5ч). Оборудование устья (3ч). | E28: 245 | H28: =H27 -> 80 | I28: 8 | J28: =IF(I28<>"",J27+I28/24,"") -> 45500.312 | K28: 80 | L28: 5 | N28: =IF(L28="","",L28-I28) -> -3 | O28: =IF(L28<>"",O27+L28/24,O27+I28/24) -> 45500.042 | Q28: 80 | R28: 8 | Z28: ч
A29: 10 | B29: ПВО | C29: Монтаж ПВО (6ч). Опрессовка глухих плашек ППГ, БГ, БД, выкидных линий, крестовины с коренными задвижками, ЗБР (1,5ч). | E29: 245 | H29: =H28 -> 80 | I29: 7.5 | J29: =IF(I29<>"",J28+I29/24,"") -> 45500.625 | K29: 80 | L29: 2 | N29: =IF(L29="","",L29-I29) -> -5.5 | O29: =IF(L29<>"",O28+L29/24,O28+I29/24) -> 45500.125 | Q29: 80 | R29: 7.5
A30: 11 | B30: КНБК | C30: Сборка КНБК для бурения. | E30: 178 | H30: =H29 -> 80 | I30: 3 | J30: =IF(I30<>"",J29+I30/24,"") -> 45500.75 | K30: 80 | L30: 2 | N30: =IF(L30="","",L30-I30) -> -1 | O30: =IF(L30<>"",O29+L30/24,O29+I30/24) -> 45500.208 | Q30: 80 | R30: 3
A31: 12 | B31: СПО | C31: Cпуск КНБК (1ч). Опрессовка трубных плашек, ПУГ (1ч). | E31: 178 | F31: 0 | G31: =G25 -> 80 | H31: =H29 -> 80 | I31: 2 | J31: =IF(I31<>"",J30+I31/24,"") -> 45500.833 | K31: 80 | L31: 0.75 | N31: =IF(L31="","",L31-I31) -> -1.25 | O31: =IF(L31<>"",O30+L31/24,O30+I31/24) -> 45500.24 | Q31: 80 | R31: 2 | AF31: м/ч бур
A32: 13 | B32: Бурение | C32: Разбурка оснастки (ЦКОД, цем.стакан, БК) Чистка ЦСГО. | E32: 178 | F32: =G31 -> 80 | G32: =E5+2 -> 82 | H32: =G32 -> 82 | I32: 2 | J32: =IF(I32<>"",J31+I32/24,"") -> 45500.917 | K32: 80 | L32: 0.25 | N32: =IF(L32="","",L32-I32) -> -1.75 | O32: =IF(L32<>"",O31+L32/24,O31+I32/24) -> 45500.25 | Q32: 82 | R32: 2 | U32: Н | V32: П | X32: Ф | Z32: св | AA32: наращ | AB32: замер | AC32: ориент | AD32: Прор | AE32: пром | AF32: 70 | AH32: сум бур
A33: 14 | B33: Бурение | C33: Бурение под кондуктор (прокачка укрепляющих пачек ч/з каждые 150-200м) | E33: 178 | F33: =H32 -> 82 | G33: 1500 | H33: =G33 -> 1500 | I33: 32 | J33: =IF(I33<>"",J32+I33/24,"") -> 45502.25 | K33: 1408 | L33: 24.75 | N33: =IF(L33="","",L33-I33) -> -7.25 | O33: =IF(L33<>"",O32+L33/24,O32+I33/24) -> 45501.281 | Q33: =H33 -> 1500 | R33: 32 | U33: 32 | V33: =(G33-F33)/I33 -> 44.3125 | X33: =(K33-K32)/(L33-M33) -> 53.656566 | Z33: =(G33-F33)/25.5 -> 55.607843 | AA33: =Z33*0.15*$E$15 -> 0 | AB33: =Z33*5/60 -> 4.6339869 | AC33: =(G33-F33)*0.33/8*5/60 -> 4.874375 | AE33: =(300^2-127^2)*3.14/4/10^6*200/70/60*1000 -> 2.7613683 | AF33: =(G33-F33)/AF32 -> 20.257143 | AH33: =SUM(AA33:AF33) -> 32.526873
A34: 15 | B34: Циркуляция и Обработка БР | C34: Промывка за 50 м до Хантымансийской свиты | E34: 178 | H34: =H33 -> 1500 | I34: 2.5 | J34: =IF(I34<>"",J33+I34/24,"") -> 45502.354 | K34: 1408 | L34: 0.5 | N34: =IF(L34="","",L34-I34) -> -2 | O34: =IF(L34<>"",O33+L34/24,O33+I34/24) -> 45501.302 | Q34: =Q33 -> 1500 | R34: 2.5 | Z34: ч
A35: 16 | B35: Шаблонирование / проработка | C35: Шаблонирование (подъем) (по согласованию с РН по ТСБ) | E35: 178 | F35: =G33 -> 1500 | H35: =H34 -> 1500 | I35: 7 | J35: =IF(I35<>"",J34+I35/24,"") -> 45502.646 | K35: 1408 | L35: 0 | N35: =IF(L35="","",L35-I35) -> -7 | O35: =IF(L35<>"",O34+L35/24,O34+I35/24) -> 45501.302 | Q35: =Q34 -> 1500 | R35: 7 | U35: 200 | V35: =(G35-F35)/I35 -> -214.28571 | X35: =(K35-K32)/(L35-M35) -> #DIV/0! | Z35: =ROUNDDOWN(0.089*$E$15*(F35-G35)/25.5,2) -> 0
A36: 17 | B36: Шаблонирование / проработка | C36: Шаблонирование (спуск) (по согласованию с РН по ТСБ) | E36: 178 | F36: 80 | G36: =G33 -> 1500 | H36: =H35 -> 1500 | I36: 6 | J36: =IF(I36<>"",J35+I36/24,"") -> 45502.896 | K36: 1408 | L36: 0 | N36: =IF(L36="","",L36-I36) -> -6 | O36: =IF(L36<>"",O35+L36/24,O35+I36/24) -> 45501.302 | Q36: =Q35 -> 1500 | R36: 6 | U36: 250 | V36: =(G36-F36)/I36 -> 236.66667 | X36: =(K36-K32)/(L36-M36) -> #DIV/0! | Z36: =ROUNDDOWN(0.085*$E$15*(G36-F36)/25.5,2) -> 0
A37: 18 | B37: Циркуляция и Обработка БР | C37: Промывка. Обновление БР (замещение) (по согласованию с РН по ТСБ) | E37: 178 | H37: =H36 -> 1500 | I37: 2 | J37: =IF(I37<>"",J36+I37/24,"") -> 45502.979 | K37: 1408 | L37: 0 | N37: =IF(L37="","",L37-I37) -> -2 | O37: =IF(L37<>"",O36+L37/24,O36+I37/24) -> 45501.302 | Q37: =Q36 -> 1500 | R37: 2
A38: 19 | B38: Бурение | C38: Бурение под кондуктор наращ.св. (прокачка укрепляющих пачек ч/з каждые 150-200м) | E38: 178 | F38: =G33 -> 1500 | G38: 2100 | H38: =G38 -> 2100 | I38: 34 | J38: =IF(I38<>"",J37+I38/24,"") -> 45504.396 | K38: 2024 | L38: 23.75 | N38: =IF(L38="","",L38-I38) -> -10.25 | O38: =IF(L38<>"",O37+L38/24,O37+I38/24) -> 45502.292 | Q38: =H38 -> 2100 | R38: 34 | U38: 270 | V38: =(G38-F38)/I38 -> 17.647059 | X38: =K38/(L38-M38) -> 85.221053
A39: 20 | B39: Циркуляция и Обработка БР | C39: Промывка за 50 м до Алымской свиты | E39: 178 | H39: 2060 | I39: 2 | J39: =IF(I39<>"",J38+I39/24,"") -> 45504.479 | K39: 2024 | L39: 0.5 | N39: =IF(L39="","",L39-I39) -> -1.5 | O39: =IF(L39<>"",O38+L39/24,O38+I39/24) -> 45502.312 | Q39: 2060 | R39: 2
A40: 21 | B40: Бурение | C40: Бурение под кондуктор наращ.св. (прокачка укрепляющих пачек ч/з каждые 150-200м) | E40: 178 | F40: =G38 -> 2100 | G40: =E6 -> 2543.15 | H40: =G40 -> 2543.15 | I40: 34 | J40: =IF(I40<>"",J39+I40/24,"") -> 45505.896 | K40: 2543 | L40: 27.75 | N40: =IF(L40="","",L40-I40) -> -6.25 | O40: =IF(L40<>"",O39+L40/24,O39+I40/24) -> 45503.469 | Q40: =H40 -> 2543.15 | R40: 34
A41: 22 | B41: Циркуляция и Обработка БР | C41: Промывка | E41: 178 | H41: =H40 -> 2543.15 | I41: 3 | J41: =IF(I41<>"",J40+I41/24,"") -> 45506.021 | K41: 2543 | L41: 1.75 | N41: =IF(L41="","",L41-I41) -> -1.25 | O41: =IF(L41<>"",O40+L41/24,O40+I41/24) -> 45503.542 | Q41: =Q40 -> 2543.15 | R41: 3
...

Sheet Для Печати
A1: Сетевой график "Глубина-день"
B2: Компания | C2: ='Глубина-день'!C3 -> ООО "Газпромнефть-Хантос"
B3: Месторождение | C3: ='Глубина-день'!C4 -> Южно-Приобское
B4: Кустовая площадка | C4: ='Глубина-день'!C5 -> 134В.1 ЮПМ
B5: Скважина № | C5: ='Глубина-день'!C6 -> 43820
B6: Руководитель направления | C6: ='Глубина-день'!C7 -> 2КК, ГС без ПС
B7: Супервайзер АО "НИПЦ ГНТ" | C7: =IF('Глубина-день'!C8="","",'Глубина-день'!C8) -> Богомягков В.А.
C8: =IF('Глубина-день'!C9="","",'Глубина-день'!C9)
C9: =IF('Глубина-день'!C10="","",'Глубина-день'!C10)
B10: Дата начала бурения | C10: =IF('глубина-день'!#ref!="","",'глубина-день'!#ref!) -> #VALUE!
A11: ='Глубина-день'!A17:E17 -> Операции | E11: ='Глубина-день'!F17:R17 -> #VALUE! | M11: ='Глубина-день'!K17:P17 -> 0
A12: # | B12: Операции | C12: Описание | D12: Секция | E12: Инт. 1 | F12: Инт. 2 | G12: Проходка | H12: Забой | I12: Время | J12: Дата окончания | K12: РГ | L12: БнБ | M12: Забой | N12: Время Факт | O12: Примечание
A13: =IF('Глубина-день'!A20="","",'Глубина-день'!A20) -> 1 | B13: =IF('Глубина-день'!B20="","",'Глубина-день'!B20) -> КНБК | C13: =IF('Глубина-день'!C20="","",'Глубина-день'!C20) -> Сборка КНБК | D13: =IF('Глубина-день'!E20="","",'Глубина-день'!E20) -> 245 | E13: =IF('Глубина-день'!F20="","",'Глубина-день'!F20) -> 0 | F13: =IF('Глубина-день'!G20="","",'Глубина-день'!G20) | G13: =IF('глубина-день'!#ref!="","",'глубина-день'!#ref!) -> #VALUE! | H13: =IF('Глубина-день'!H20="","",'Глубина-день'!H20) -> 0 | I13: =IF('Глубина-день'!I20="","",'Глубина-день'!I20) -> 0.5 | J13: =IF('Глубина-день'!J20="","",'Глубина-день'!J20) -> 45499.646 | K13: =IF('Глубина-день'!R20="","",'Глубина-день'!R20) -> 0.5 | L13: =IF('глубина-день'!#ref!="","",'глубина-день'!#ref!) -> #VALUE!
A14: =IF('Глубина-день'!A21="","",'Глубина-день'!A21) -> 2 | B14: =IF('Глубина-день'!B21="","",'Глубина-день'!B21) -> Бурение | C14: =IF('Глубина-день'!C21="","",'Глубина-день'!C21) -> Бурение под направление | D14: =IF('Глубина-день'!E21="","",'Глубина-день'!E21) -> 245 | E14: =IF('Глубина-день'!F21="","",'Глубина-день'!F21) -> 0 | F14: =IF('Глубина-день'!G21="","",'Глубина-день'!G21) -> 80 | G14: =IF('глубина-день'!#ref!="","",'глубина-день'!#ref!) -> #VALUE! | H14: =IF('Глубина-день'!H21="","",'Глубина-день'!H21) -> 80 | I14: =IF('Глубина-день'!I21="","",'Глубина-день'!I21) -> 2 | J14: =IF('Глубина-день'!J21="","",'Глубина-день'!J21) -> 45499.729 | K14: =IF('Глубина-день'!R21="","",'Глубина-день'!R21) -> 2 | L14: =IF('глубина-день'!#ref!="","",'глубина-день'!#ref!) -> #VALUE!
A15: =IF('Глубина-день'!A22="","",'Глубина-день'!A22) -> 3 | B15: =IF('Глубина-день'!B22="","",'Глубина-день'!B22) -> Шаблонирование / проработка | C15: =IF('Глубина-день'!C22="","",'Глубина-день'!C22) -> Шаблонирование перед спуском | D15: =IF('Глубина-день'!E22="","",'Глубина-день'!E22) -> 245 | E15: =IF('Глубина-день'!F22="","",'Глубина-день'!F22) -> 0 | F15: =IF('Глубина-день'!G22="","",'Глубина-день'!G22) -> 80 | G15: =IF('глубина-день'!#ref!="","",'глубина-день'!#ref!) -> #VALUE! | H15: =IF('Глубина-день'!H22="","",'Глубина-день'!H22) -> 80 | I15: =IF('Глубина-день'!I22="","",'Глубина-день'!I22) -> 1 | J15: =IF('Глубина-день'!J22="","",'Глубина-день'!J22) -> 45499.771 | K15: =IF('Глубина-день'!R22="","",'Глубина-день'!R22) -> 1 | L15: =IF('глубина-день'!#ref!="","",'глубина-день'!#ref!) -> #VALUE!
A16: =IF('Глубина-день'!A23="","",'Глубина-день'!A23) -> 4 | B16: =IF('Глубина-день'!B23="","",'Глубина-день'!B23) -> КНБК | C16: =IF('Глубина-день'!C23="","",'Глубина-день'!C23) -> Разборка КНБК | D16: =IF('Глубина-день'!E23="","",'Глубина-день'!E23) -> 245 | E16: =IF('Глубина-день'!F23="","",'Глубина-день'!F23) | F16: =IF('Глубина-день'!G23="","",'Глубина-день'!G23) | G16: =IF('глубина-день'!#ref!="","",'глубина-день'!#ref!) -> #VALUE! | H16: =IF('Глубина-день'!H23="","",'Глубина-день'!H23) -> 80 | I16: =IF('Глубина-день'!I23="","",'Глубина-день'!I23) -> 0.5 | J16: =IF('Глубина-день'!J23="","",'Глубина-день'!J23) -> 45499.792 | K16: =IF('Глубина-день'!R23="","",'Глубина-день'!R23) -> 0.5 | L16: =IF('глубина-день'!#ref!="","",'глубина-день'!#ref!) -> #VALUE!
A17: =IF('Глубина-день'!A24="","",'Глубина-день'!A24) -> 5 | B17: =IF('Глубина-день'!B24="","",'Глубина-день'!B24) -> Подготовительные работы | C17: =IF('Глубина-день'!C24="","",'Глубина-день'!C24) -> ПР к спуску направления 245 мм | D17: =IF('Глубина-день'!E24="","",'Глубина-день'!E24) -> 245 | E17: =IF('Глубина-день'!F24="","",'Глубина-день'!F24) | F17: =IF('Глубина-день'!G24="","",'Глубина-день'!G24) | G17: =IF('глубина-день'!#ref!="","",'глубина-день'!#ref!) -> #VALUE! | H17: =IF('Глубина-день'!H24="","",'Глубина-день'!H24) -> 80 | I17: =IF('Глубина-день'!I24="","",'Глубина-день'!I24) -> 0.5 | J17: =IF('Глубина-день'!J24="","",'Глубина-день'!J24) -> 45499.812 | K17: =IF('Глубина-день'!R24="","",'Глубина-день'!R24) -> 0.5 | L17: =IF('глубина-день'!#ref!="","",'глубина-день'!#ref!) -> #VALUE!
A18: =IF('Глубина-день'!A25="","",'Глубина-день'!A25) -> 6 | B18: =IF('Глубина-день'!B25="","",'Глубина-день'!B25) -> Крепление | C18: =IF('Глубина-день'!C25="","",'Глубина-день'!C25) -> Спуск направления | D18: =IF('Глубина-день'!E25="","",'Глубина-день'!E25) -> 245 | E18: =IF('Глубина-день'!F25="","",'Глубина-день'!F25) -> 0 | F18: =IF('Глубина-день'!G25="","",'Глубина-день'!G25) -> 80 | G18: =IF('глубина-день'!#ref!="","",'глубина-день'!#ref!) -> #VALUE! | H18: =IF('Глубина-день'!H25="","",'Глубина-день'!H25) -> 80 | I18: =IF('Глубина-день'!I25="","",'Глубина-день'!I25) -> 2 | J18: =IF('Глубина-день'!J25="","",'Глубина-день'!J25) -> 45499.896 | K18: =IF('Глубина-день'!R25="","",'Глубина-день'!R25) -> 2 | L18: =IF('глубина-день'!#ref!="","",'глубина-день'!#ref!) -> #VALUE!
A19: =IF('Глубина-день'!A26="","",'Глубина-день'!A26) -> 7 | B19: =IF('Глубина-день'!B26="","",'Глубина-день'!B26) -> Циркуляция и Обработка БР | C19: =IF('Глубина-день'!C26="","",'Глубина-день'!C26) -> Промывка перед цементажем | D19: =IF('Глубина-день'!E26="","",'Глубина-день'!E26) -> 245 | E19: =IF('Глубина-день'!F26="","",'Глубина-день'!F26) | F19: =IF('Глубина-день'!G26="","",'Глубина-день'!G26) | G19: =IF('глубина-день'!#ref!="","",'глубина-день'!#ref!) -> #VALUE! | H19: =IF('Глубина-день'!H26="","",'Глубина-день'!H26) -> 80 | I19: =IF('Глубина-день'!I26="","",'Глубина-день'!I26) -> 0.5 | J19: =IF('Глубина-день'!J26="","",'Глубина-день'!J26) -> 45499.917 | K19: =IF('Глубина-день'!R26="","",'Глубина-день'!R26) -> 0.5 | L19: =IF('глубина-день'!#ref!="","",'глубина-день'!#ref!) -> #VALUE!
A20: =IF('Глубина-день'!A27="","",'Глубина-день'!A27) -> 8 | B20: =IF('Глубина-день'!B27="","",'Глубина-день'!B27) -> Крепление | C20: =IF('Глубина-день'!C27="","",'Глубина-день'!C27) -> Цементаж направления 245мм | D20: =IF('Глубина-день'!E27="","",'Глубина-день'!E27) -> 245 | E20: =IF('Глубина-день'!F27="","",'Глубина-день'!F27) | F20: =IF('Глубина-день'!G27="","",'Глубина-день'!G27) | G20: =IF('глубина-день'!#ref!="","",'глубина-день'!#ref!) -> #VALUE! | H20: =IF('Глубина-день'!H27="","",'Глубина-день'!H27) -> 80 | I20: =IF('Глубина-день'!I27="","",'Глубина-день'!I27) -> 1.5 | J20: =IF('Глубина-день'!J27="","",'Глубина-день'!J27) -> 45499.979 | K20: =IF('Глубина-день'!R27="","",'Глубина-день'!R27) -> 1.5 | L20: =IF('глубина-день'!#ref!="","",'глубина-день'!#ref!) -> #VALUE!
A21: =IF('глубина-день'!#ref!="","",'глубина-день'!#ref!) -> #VALUE! | B21: =IF('глубина-день'!#ref!="","",'глубина-день'!#ref!) -> #VALUE! | C21: =IF('глубина-день'!#ref!="","",'глубина-день'!#ref!) -> #VALUE! | D21: =IF('глубина-день'!#ref!="","",'глубина-день'!#ref!) -> #VALUE! | E21: =IF('глубина-день'!#ref!="","",'глубина-день'!#ref!) -> #VALUE! | F21: =IF('глубина-день'!#ref!="","",'глубина-день'!#ref!) -> #VALUE! | G21: =IF('глубина-день'!#ref!="","",'глубина-день'!#ref!) -> #VALUE! | H21: =IF('глубина-день'!#ref!="","",'глубина-день'!#ref!) -> #VALUE! | ... L21: =IF('глубина-день'!#ref!="","",'глубина-день'!#ref!) -> #VALUE!
A22: =IF('Глубина-день'!A29="","",'Глубина-день'!A29) -> 10 | B22: =IF('Глубина-день'!B29="","",'Глубина-день'!B29) -> ПВО | C22: =IF('Глубина-день'!C29="","",'Глубина-день'!C29) -> Монтаж ПВО (6ч). Опрессовка глухих плашек ППГ, БГ, БД, выкидных линий, крестовины с коренными задвижками, ЗБР (1,5ч). | D22: =IF('Глубина-день'!E29="","",'Глубина-день'!E29) -> 245 | E22: =IF('Глубина-день'!F29="","",'Глубина-день'!F29) | F22: =IF('Глубина-день'!G29="","",'Глубина-день'!G29) | G22: =IF('глубина-день'!#ref!="","",'глубина-день'!#ref!) -> #VALUE! | H22: =IF('Глубина-день'!H29="","",'Глубина-день'!H29) -> 80 | I22: =IF('Глубина-день'!I29="","",'Глубина-день'!I29) -> 7.5 | J22: =IF('Глубина-день'!J29="","",'Глубина-день'!J29) -> 45500.625 | K22: =IF('Глубина-день'!R29="","",'Глубина-день'!R29) -> 7.5 | L22: =IF('глубина-день'!#ref!="","",'глубина-день'!#ref!) -> #VALUE!
A23: =IF('Глубина-день'!A31="","",'Глубина-день'!A31) -> 12 | B23: =IF('Глубина-день'!B31="","",'Глубина-день'!B31) -> СПО | C23: =IF('Глубина-день'!C31="","",'Глубина-день'!C31) -> Cпуск КНБК (1ч). Опрессовка трубных плашек, ПУГ (1ч). | D23: =IF('Глубина-день'!E31="","",'Глубина-день'!E31) -> 178 | E23: =IF('Глубина-день'!F31="","",'Глубина-день'!F31) -> 0 | F23: =IF('Глубина-день'!G31="","",'Глубина-день'!G31) -> 80 | G23: =IF('глубина-день'!#ref!="","",'глубина-день'!#ref!) -> #VALUE! | H23: =IF('Глубина-день'!H31="","",'Глубина-день'!H31) -> 80 | I23: =IF('Глубина-день'!I31="","",'Глубина-день'!I31) -> 2 | J23: =IF('Глубина-день'!J31="","",'Глубина-день'!J31) -> 45500.833 | K23: =IF('Глубина-день'!R31="","",'Глубина-день'!R31) -> 2 | L23: =IF('глубина-день'!#ref!="","",'глубина-день'!#ref!) -> #VALUE!
A24: =IF('Глубина-день'!A32="","",'Глубина-день'!A32) -> 13 | B24: =IF('Глубина-день'!B32="","",'Глубина-день'!B32) -> Бурение | C24: =IF('Глубина-день'!C32="","",'Глубина-день'!C32) -> Разбурка оснастки (ЦКОД, цем.стакан, БК) Чистка ЦСГО. | D24: =IF('Глубина-день'!E32="","",'Глубина-день'!E32) -> 178 | E24: =IF('Глубина-день'!F32="","",'Глубина-день'!F32) -> 80 | F24: =IF('Глубина-день'!G32="","",'Глубина-день'!G32) -> 82 | G24: =IF('глубина-день'!#ref!="","",'глубина-день'!#ref!) -> #VALUE! | H24: =IF('Глубина-день'!H32="","",'Глубина-день'!H32) -> 82 | I24: =IF('Глубина-день'!I32="","",'Глубина-день'!I32) -> 2 | J24: =IF('Глубина-день'!J32="","",'Глубина-день'!J32) -> 45500.917 | K24: =IF('Глубина-день'!R32="","",'Глубина-день'!R32) -> 2 | L24: =IF('глубина-день'!#ref!="","",'глубина-день'!#ref!) -> #VALUE!
A25: =IF('Глубина-день'!A33="","",'Глубина-день'!A33) -> 14 | B25: =IF('Глубина-день'!B33="","",'Глубина-день'!B33) -> Бурение | C25: =IF('Глубина-день'!C33="","",'Глубина-день'!C33) -> Бурение под кондуктор (прокачка укрепляющих пачек ч/з каждые 150-200м) | D25: =IF('Глубина-день'!E33="","",'Глубина-день'!E33) -> 178 | E25: =IF('Глубина-день'!F33="","",'Глубина-день'!F33) -> 82 | F25: =IF('Глубина-день'!G33="","",'Глубина-день'!G33) -> 1500 | G25: =IF('глубина-день'!#ref!="","",'глубина-день'!#ref!) -> #VALUE! | H25: =IF('Глубина-день'!H33="","",'Глубина-день'!H33) -> 1500 | I25: =IF('Глубина-день'!I33="","",'Глубина-день'!I33) -> 32 | J25: =IF('Глубина-день'!J33="","",'Глубина-день'!J33) -> 45502.25 | K25: =IF('Глубина-день'!R33="","",'Глубина-день'!R33) -> 32 | L25: =IF('глубина-день'!#ref!="","",'глубина-день'!#ref!) -> #VALUE!
A26: =IF('Глубина-день'!A34="","",'Глубина-день'!A34) -> 15 | B26: =IF('Глубина-день'!B34="","",'Глубина-день'!B34) -> Циркуляция и Обработка БР | C26: =IF('Глубина-день'!C34="","",'Глубина-день'!C34) -> Промывка за 50 м до Хантымансийской свиты | D26: =IF('Глубина-день'!E34="","",'Глубина-день'!E34) -> 178 | E26: =IF('Глубина-день'!F34="","",'Глубина-день'!F34) | F26: =IF('Глубина-день'!G34="","",'Глубина-день'!G34) | G26: =IF('глубина-день'!#ref!="","",'глубина-день'!#ref!) -> #VALUE! | H26: =IF('Глубина-день'!H34="","",'Глубина-день'!H34) -> 1500 | I26: =IF('Глубина-день'!I34="","",'Глубина-день'!I34) -> 2.5 | J26: =IF('Глубина-день'!J34="","",'Глубина-день'!J34) -> 45502.354 | K26: =IF('Глубина-день'!R34="","",'Глубина-день'!R34) -> 2.5 | L26: =IF('глубина-день'!#ref!="","",'глубина-день'!#ref!) -> #VALUE!
A27: =IF('Глубина-день'!A35="","",'Глубина-день'!A35) -> 16 | B27: =IF('Глубина-день'!B35="","",'Глубина-день'!B35) -> Шаблонирование / проработка | C27: =IF('Глубина-день'!C35="","",'Глубина-день'!C35) -> Шаблонирование (подъем) (по согласованию с РН по ТСБ) | D27: =IF('Глубина-день'!E35="","",'Глубина-день'!E35) -> 178 | E27: =IF('Глубина-день'!F35="","",'Глубина-день'!F35) -> 1500 | F27: =IF('Глубина-день'!G35="","",'Глубина-день'!G35) | G27: =IF('глубина-день'!#ref!="","",'глубина-день'!#ref!) -> #VALUE! | H27: =IF('Глубина-день'!H35="","",'Глубина-день'!H35) -> 1500 | I27: =IF('Глубина-день'!I35="","",'Глубина-день'!I35) -> 7 | J27: =IF('Глубина-день'!J35="","",'Глубина-день'!J35) -> 45502.646 | K27: =IF('Глубина-день'!R35="","",'Глубина-день'!R35) -> 7 | L27: =IF('глубина-день'!#ref!="","",'глубина-день'!#ref!) -> #VALUE!
A28: =IF('Глубина-день'!A36="","",'Глубина-день'!A36) -> 17 | B28: =IF('Глубина-день'!B36="","",'Глубина-день'!B36) -> Шаблонирование / проработка | C28: =IF('Глубина-день'!C36="","",'Глубина-день'!C36) -> Шаблонирование (спуск) (по согласованию с РН по ТСБ) | D28: =IF('Глубина-день'!E36="","",'Глубина-день'!E36) -> 178 | E28: =IF('Глубина-день'!F36="","",'Глубина-день'!F36) -> 80 | F28: =IF('Глубина-день'!G36="","",'Глубина-день'!G36) -> 1500 | G28: =IF('глубина-день'!#ref!="","",'глубина-день'!#ref!) -> #VALUE! | H28: =IF('Глубина-день'!H36="","",'Глубина-день'!H36) -> 1500 | I28: =IF('Глубина-день'!I36="","",'Глубина-день'!I36) -> 6 | J28: =IF('Глубина-день'!J36="","",'Глубина-день'!J36) -> 45502.896 | K28: =IF('Глубина-день'!R36="","",'Глубина-день'!R36) -> 6 | L28: =IF('глубина-день'!#ref!="","",'глубина-день'!#ref!) -> #VALUE!
A29: =IF('Глубина-день'!A37="","",'Глубина-день'!A37) -> 18 | B29: =IF('Глубина-день'!B37="","",'Глубина-день'!B37) -> Циркуляция и Обработка БР | C29: =IF('Глубина-день'!C37="","",'Глубина-день'!C37) -> Промывка. Обновление БР (замещение) (по согласованию с РН по ТСБ) | D29: =IF('Глубина-день'!E37="","",'Глубина-день'!E37) -> 178 | E29: =IF('Глубина-день'!F37="","",'Глубина-день'!F37) | F29: =IF('Глубина-день'!G37="","",'Глубина-день'!G37) | G29: =IF('глубина-день'!#ref!="","",'глубина-день'!#ref!) -> #VALUE! | H29: =IF('Глубина-день'!H37="","",'Глубина-день'!H37) -> 1500 | I29: =IF('Глубина-день'!I37="","",'Глубина-день'!I37) -> 2 | J29: =IF('Глубина-день'!J37="","",'Глубина-день'!J37) -> 45502.979 | K29: =IF('Глубина-день'!R37="","",'Глубина-день'!R37) -> 2 | L29: =IF('глубина-день'!#ref!="","",'глубина-день'!#ref!) -> #VALUE!
A30: =IF('Глубина-день'!A38="","",'Глубина-день'!A38) -> 19 | B30: =IF('Глубина-день'!B38="","",'Глубина-день'!B38) -> Бурение | C30: =IF('Глубина-день'!C38="","",'Глубина-день'!C38) -> Бурение под кондуктор наращ.св. (прокачка укрепляющих пачек ч/з каждые 150-200м) | D30: =IF('Глубина-день'!E38="","",'Глубина-день'!E38) -> 178 | E30: =IF('Глубина-день'!F38="","",'Глубина-день'!F38) -> 1500 | F30: =IF('Глубина-день'!G38="","",'Глубина-день'!G38) -> 2100 | G30: =IF('глубина-день'!#ref!="","",'глубина-день'!#ref!) -> #VALUE! | H30: =IF('Глубина-день'!H38="","",'Глубина-день'!H38) -> 2100 | I30: =IF('Глубина-день'!I38="","",'Глубина-день'!I38) -> 34 | J30: =IF('Глубина-день'!J38="","",'Глубина-день'!J38) -> 45504.396 | K30: =IF('Глубина-день'!R38="","",'Глубина-день'!R38) -> 34 | L30: =IF('глубина-день'!#ref!="","",'глубина-день'!#ref!) -> #VALUE!
A31: =IF('Глубина-день'!A47="","",'Глубина-день'!A47) -> 28 | B31: =IF('Глубина-день'!B47="","",'Глубина-день'!B47) -> Подготовительные работы | C31: =IF('Глубина-день'!C47="","",'Глубина-день'!C47) -> ПЗР к спуску 178мм ОК | D31: =IF('Глубина-день'!E47="","",'Глубина-день'!E47) -> 178 | E31: =IF('Глубина-день'!F47="","",'Глубина-день'!F47) | F31: =IF('Глубина-день'!G47="","",'Глубина-день'!G47) | G31: =IF('глубина-день'!#ref!="","",'глубина-день'!#ref!) -> #VALUE! | H31: =IF('Глубина-день'!H47="","",'Глубина-день'!H47) -> 2543.15 | I31: =IF('Глубина-день'!I47="","",'Глубина-день'!I47) -> 1 | J31: =IF('Глубина-день'!J47="","",'Глубина-день'!J47) -> 45507.479 | K31: =IF('Глубина-день'!R47="","",'Глубина-день'!R47) -> 1 | L31: =IF('глубина-день'!#ref!="","",'глубина-день'!#ref!) -> #VALUE!
A32: =IF('Глубина-день'!A48="","",'Глубина-день'!A48) -> 29 | B32: =IF('Глубина-день'!B48="","",'Глубина-день'!B48) -> Крепление | C32: =IF('Глубина-день'!C48="","",'Глубина-день'!C48) -> Спуск 178мм ОК с промывками | D32: =IF('Глубина-день'!E48="","",'Глубина-день'!E48) -> 178 | E32: =IF('Глубина-день'!F48="","",'Глубина-день'!F48) | F32: =IF('Глубина-день'!G48="","",'Глубина-день'!G48) | G32: =IF('глубина-день'!#ref!="","",'глубина-день'!#ref!) -> #VALUE! | H32: =IF('Глубина-день'!H48="","",'Глубина-день'!H48) -> 2543.15 | I32: =IF('Глубина-день'!I48="","",'Глубина-день'!I48) -> 18 | J32: =IF('Глубина-день'!J48="","",'Глубина-день'!J48) -> 45508.229 | K32: =IF('Глубина-день'!R48="","",'Глубина-день'!R48) -> 18 | L32: =IF('глубина-день'!#ref!="","",'глубина-день'!#ref!) -> #VALUE!
A33: =IF('Глубина-день'!A49="","",'Глубина-день'!A49) -> 30 | B33: =IF('Глубина-день'!B49="","",'Глубина-день'!B49) -> Циркуляция и Обработка БР | C33: =IF('Глубина-день'!C49="","",'Глубина-день'!C49) -> Промывка | D33: =IF('Глубина-день'!E49="","",'Глубина-день'!E49) -> 178 | E33: =IF('Глубина-день'!F49="","",'Глубина-день'!F49) | F33: =IF('Глубина-день'!G49="","",'Глубина-день'!G49) | G33: =IF('глубина-день'!#ref!="","",'глубина-день'!#ref!) -> #VALUE! | H33: =IF('Глубина-день'!H49="","",'Глубина-день'!H49) -> 2543.15 | I33: =IF('Глубина-день'!I49="","",'Глубина-день'!I49) -> 2 | J33: =IF('Глубина-день'!J49="","",'Глубина-день'!J49) -> 45508.312 | K33: =IF('Глубина-день'!R49="","",'Глубина-день'!R49) -> 2 | L33: =IF('глубина-день'!#ref!="","",'глубина-день'!#ref!) -> #VALUE!
A34: =IF('Глубина-день'!A50="","",'Глубина-день'!A50) -> 31 | B34: =IF('Глубина-день'!B50="","",'Глубина-день'!B50) -> Крепление | C34: =IF('Глубина-день'!C50="","",'Глубина-день'!C50) -> Цементирование 178мм ОК | D34: =IF('Глубина-день'!E50="","",'Глубина-день'!E50) -> 178 | E34: =IF('Глубина-день'!F50="","",'Глубина-день'!F50) | F34: =IF('Глубина-день'!G50="","",'Глубина-день'!G50) | G34: =IF('глубина-день'!#ref!="","",'глубина-день'!#ref!) -> #VALUE! | H34: =IF('Глубина-день'!H50="","",'Глубина-день'!H50) -> 2543.15 | I34: =IF('Глубина-день'!I50="","",'Глубина-день'!I50) -> 4 | J34: =IF('Глубина-день'!J50="","",'Глубина-день'!J50) -> 45508.479 | K34: =IF('Глубина-день'!R50="","",'Глубина-день'!R50) -> 4 | L34: =IF('глубина-день'!#ref!="","",'глубина-день'!#ref!) -> #VALUE!
A35: =IF('Глубина-день'!A51="","",'Глубина-день'!A51) -> 32 | B35: =IF('Глубина-день'!B51="","",'Глубина-день'!B51) -> Крепление | C35: =IF('Глубина-день'!C51="","",'Глубина-день'!C51) -> Перемонтаж (Демонтаж ПВО ( переоборудование устья скважины), чистка емкостей, вывоз/заготовка РУО | D35: =IF('Глубина-день'!E51="","",'Глубина-день'!E51) -> 178 | E35: =IF('Глубина-день'!F51="","",'Глубина-день'!F51) | F35: =IF('Глубина-день'!G51="","",'Глубина-день'!G51) | G35: =IF('глубина-день'!#ref!="","",'глубина-день'!#ref!) -> #VALUE! | H35: =IF('Глубина-день'!H51="","",'Глубина-день'!H51) -> 2543.15 | I35: =IF('Глубина-день'!I51="","",'Глубина-день'!I51) -> 4 | J35: =IF('Глубина-день'!J51="","",'Глубина-день'!J51) -> 45508.646 | K35: =IF('Глубина-день'!R51="","",'Глубина-день'!R51) -> 4 | L35: =IF('глубина-день'!#ref!="","",'глубина-день'!#ref!) -> #VALUE!
A36: =IF('Глубина-день'!A52="","",'Глубина-день'!A52) -> 33 | B36: =IF('Глубина-день'!B52="","",'Глубина-день'!B52) -> Крепление | C36: =IF('Глубина-день'!C52="","",'Глубина-день'!C52) -> Перемонтаж (Монтаж ПВО повторный (смена плашек ПВО), ЗБР, чистка емкостей, вывоз/заготовка РУО | D36: =IF('Глубина-день'!E52="","",'Глубина-день'!E52) -> 178 | E36: =IF('Глубина-день'!F52="","",'Глубина-день'!F52) | F36: =IF('Глубина-день'!G52="","",'Глубина-день'!G52) | G36: =IF('глубина-день'!#ref!="","",'глубина-день'!#ref!) -> #VALUE! | H36: =IF('Глубина-день'!H52="","",'Глубина-день'!H52) -> 2543.15 | I36: =IF('Глубина-день'!I52="","",'Глубина-день'!I52) -> 6 | J36: =IF('Глубина-день'!J52="","",'Глубина-день'!J52) -> 45508.896 | K36: =IF('Глубина-день'!R52="","",'Глубина-день'!R52) -> 6 | L36: =IF('глубина-день'!#ref!="","",'глубина-день'!#ref!) -> #VALUE!
A37: =IF('глубина-день'!#ref!="","",'глубина-день'!#ref!) -> #VALUE! | B37: =IF('глубина-день'!#ref!="","",'глубина-день'!#ref!) -> #VALUE! | C37: =IF('глубина-день'!#ref!="","",'глубина-день'!#ref!) -> #VALUE! | D37: =IF('глубина-день'!#ref!="","",'глубина-день'!#ref!) -> #VALUE! | E37: =IF('глубина-день'!#ref!="","",'глубина-день'!#ref!) -> #VALUE! | F37: =IF('глубина-день'!#ref!="","",'глубина-день'!#ref!) -> #VALUE! | G37: =IF('глубина-день'!#ref!="","",'глубина-день'!#ref!) -> #VALUE! | H37: =IF('глубина-день'!#ref!="","",'глубина-день'!#ref!) -> #VALUE! | ... L37: =IF('глубина-день'!#ref!="","",'глубина-день'!#ref!) -> #VALUE!
A38: =IF('глубина-день'!#ref!="","",'глубина-день'!#ref!) -> #VALUE! | B38: =IF('глубина-день'!#ref!="","",'глубина-день'!#ref!) -> #VALUE! | C38: =IF('глубина-день'!#ref!="","",'глубина-день'!#ref!) -> #VALUE! | D38: =IF('глубина-день'!#ref!="","",'глубина-день'!#ref!) -> #VALUE! | E38: =IF('глубина-день'!#ref!="","",'глубина-день'!#ref!) -> #VALUE! | F38: =IF('глубина-день'!#ref!="","",'глубина-день'!#ref!) -> #VALUE! | G38: =IF('глубина-день'!#ref!="","",'глубина-день'!#ref!) -> #VALUE! | H38: =IF('глубина-день'!#ref!="","",'глубина-день'!#ref!) -> #VALUE! | ... L38: =IF('глубина-день'!#ref!="","",'глубина-день'!#ref!) -> #VALUE!
A39: =IF('глубина-день'!#ref!="","",'глубина-день'!#ref!) -> #VALUE! | B39: =IF('глубина-день'!#ref!="","",'глубина-день'!#ref!) -> #VALUE! | C39: =IF('глубина-день'!#ref!="","",'глубина-день'!#ref!) -> #VALUE! | D39: =IF('глубина-день'!#ref!="","",'глубина-день'!#ref!) -> #VALUE! | E39: =IF('глубина-день'!#ref!="","",'глубина-день'!#ref!) -> #VALUE! | F39: =IF('глубина-день'!#ref!="","",'глубина-день'!#ref!) -> #VALUE! | G39: =IF('глубина-день'!#ref!="","",'глубина-день'!#ref!) -> #VALUE! | H39: =IF('глубина-день'!#ref!="","",'глубина-день'!#ref!) -> #VALUE! | ... L39: =IF('глубина-день'!#ref!="","",'глубина-день'!#ref!) -> #VALUE!
A40: =IF('глубина-день'!#ref!="","",'глубина-день'!#ref!) -> #VALUE! | B40: =IF('глубина-день'!#ref!="","",'глубина-день'!#ref!) -> #VALUE! | C40: =IF('глубина-день'!#ref!="","",'глубина-день'!#ref!) -> #VALUE! | D40: =IF('глубина-день'!#ref!="","",'глубина-день'!#ref!) -> #VALUE! | E40: =IF('глубина-день'!#ref!="","",'глубина-день'!#ref!) -> #VALUE! | F40: =IF('глубина-день'!#ref!="","",'глубина-день'!#ref!) -> #VALUE! | G40: =IF('глубина-день'!#ref!="","",'глубина-день'!#ref!) -> #VALUE! | H40: =IF('глубина-день'!#ref!="","",'глубина-день'!#ref!) -> #VALUE! | ... L40: =IF('глубина-день'!#ref!="","",'глубина-день'!#ref!) -> #VALUE!
...

Sheet Графики
Y4: Забой | Z4: ='Глубина-день'!I18 -> Время | AB4: Забой | AC4: Факт/прогноз | AE4: План для Бонуса
Z5: Время | AA5: Суммарное | AC5: Время | AD5: Суммарное | AE5: Время | AF5: Суммарное
X6: ='Глубина-день'!A20 -> 1 | Z6: ='Глубина-день'!I20 -> 0.5 | AA6: =Z6/24 -> 0.020833333 | AB6: =IF('Глубина-день'!K21="",'Глубина-день'!K20,'Глубина-день'!K20) -> 0 | AC6: =IF('Глубина-день'!L20="",'Глубина-день'!I20,'Глубина-день'!L20) -> 0.25 | AD6: =AC6/24 -> 0.010416667 | AE6: ='Глубина-день'!R20 -> 0.5 | AF6: =AE6/24 -> 0.020833333
X7: ='Глубина-день'!A21 -> 2 | Y7: ='Глубина-день'!H21 -> 80 | Z7: ='Глубина-день'!I21 -> 2 | AA7: =Z7/24+AA6 -> 0.10416667 | AB7: =IF('Глубина-день'!K22="",'Глубина-день'!K21,'Глубина-день'!K21) -> 80 | AC7: =IF('Глубина-день'!L21="",'Глубина-день'!I21,'Глубина-день'!L21) -> 1 | AD7: =AC7/24+AD6 -> 0.052083333 | AE7: ='Глубина-день'!R21 -> 2 | AF7: =AE7/24+AF6 -> 0.10416667
X8: ='Глубина-день'!A22 -> 3 | Y8: ='Глубина-день'!H22 -> 80 | Z8: ='Глубина-день'!I22 -> 1 | AA8: =Z8/24+AA7 -> 0.14583333 | AB8: =IF('Глубина-день'!K23="",'Глубина-день'!K22,'Глубина-день'!K22) -> 80 | AC8: =IF('Глубина-день'!L22="",'Глубина-день'!I22,'Глубина-день'!L22) -> 0.5 | AD8: =AC8/24+AD7 -> 0.072916667 | AE8: ='Глубина-день'!R22 -> 1 | AF8: =AE8/24+AF7 -> 0.14583333
X9: ='Глубина-день'!A23 -> 4 | Y9: ='Глубина-день'!H23 -> 80 | Z9: ='Глубина-день'!I23 -> 0.5 | AA9: =Z9/24+AA8 -> 0.16666667 | AB9: =IF('Глубина-день'!K24="",'Глубина-день'!K23,'Глубина-день'!K23) -> 80 | AC9: =IF('Глубина-день'!L23="",'Глубина-день'!I23,'Глубина-день'!L23) -> 0.5 | AD9: =AC9/24+AD8 -> 0.09375 | AE9: ='Глубина-день'!R23 -> 0.5 | AF9: =AE9/24+AF8 -> 0.16666667
X10: ='Глубина-день'!A24 -> 5 | Y10: ='Глубина-день'!H24 -> 80 | Z10: ='Глубина-день'!I24 -> 0.5 | AA10: =Z10/24+AA9 -> 0.1875 | AB10: =IF('Глубина-день'!K25="",'Глубина-день'!K24,'Глубина-день'!K24) -> 80 | AC10: =IF('Глубина-день'!L24="",'Глубина-день'!I24,'Глубина-день'!L24) -> 0.25 | AD10: =AC10/24+AD9 -> 0.10416667 | AE10: ='Глубина-день'!R24 -> 0.5 | AF10: =AE10/24+AF9 -> 0.1875
X11: ='Глубина-день'!A25 -> 6 | Y11: ='Глубина-день'!H25 -> 80 | Z11: ='Глубина-день'!I25 -> 2 | AA11: =Z11/24+AA10 -> 0.27083333 | AB11: =IF('Глубина-день'!K26="",'Глубина-день'!K25,'Глубина-день'!K25) -> 80 | AC11: =IF('Глубина-день'!L25="",'Глубина-день'!I25,'Глубина-день'!L25) -> 1.25 | AD11: =AC11/24+AD10 -> 0.15625 | AE11: ='Глубина-день'!R25 -> 2 | AF11: =AE11/24+AF10 -> 0.27083333
X12: ='Глубина-день'!A26 -> 7 | Y12: ='Глубина-день'!H26 -> 80 | Z12: ='Глубина-день'!I26 -> 0.5 | AA12: =Z12/24+AA11 -> 0.29166667 | AB12: =IF('Глубина-день'!K27="",'Глубина-день'!K26,'Глубина-день'!K26) -> 80 | AC12: =IF('Глубина-день'!L26="",'Глубина-день'!I26,'Глубина-день'!L26) -> 0.25 | AD12: =AC12/24+AD11 -> 0.16666667 | AE12: ='Глубина-день'!R26 -> 0.5 | AF12: =AE12/24+AF11 -> 0.29166667
X13: ='Глубина-день'!A27 -> 8 | Y13: ='Глубина-день'!H27 -> 80 | Z13: ='Глубина-день'!I27 -> 1.5 | AA13: =Z13/24+AA12 -> 0.35416667 | AB13: =IF('Глубина-день'!K28="",'Глубина-день'!K27,'Глубина-день'!K27) -> 80 | AC13: =IF('Глубина-день'!L27="",'Глубина-день'!I27,'Глубина-день'!L27) -> 1 | AD13: =AC13/24+AD12 -> 0.20833333 | AE13: ='Глубина-день'!R27 -> 1.5 | AF13: =AE13/24+AF12 -> 0.35416667
X14: ='Глубина-день'!A28 -> 9 | Y14: ='Глубина-день'!H28 -> 80 | Z14: ='Глубина-день'!I28 -> 8 | AA14: =Z14/24+AA13 -> 0.6875 | AB14: =IF('Глубина-день'!K29="",'Глубина-день'!K28,'Глубина-день'!K28) -> 80 | AC14: =IF('Глубина-день'!L28="",'Глубина-день'!I28,'Глубина-день'!L28) -> 5 | AD14: =AC14/24+AD13 -> 0.41666667 | AE14: ='Глубина-день'!R28 -> 8 | AF14: =AE14/24+AF13 -> 0.6875
X15: ='Глубина-день'!A29 -> 10 | Y15: ='Глубина-день'!H29 -> 80 | Z15: ='Глубина-день'!I29 -> 7.5 | AA15: =Z15/24+AA14 -> 1 | AB15: =IF('Глубина-день'!K30="",'Глубина-день'!K29,'Глубина-день'!K29) -> 80 | AC15: =IF('Глубина-день'!L29="",'Глубина-день'!I29,'Глубина-день'!L29) -> 2 | AD15: =AC15/24+AD14 -> 0.5 | AE15: ='Глубина-день'!R29 -> 7.5 | AF15: =AE15/24+AF14 -> 1
X16: ='Глубина-день'!A30 -> 11 | Y16: ='Глубина-день'!H30 -> 80 | Z16: ='Глубина-день'!I30 -> 3 | AA16: =Z16/24+AA15 -> 1.125 | AB16: =IF('Глубина-день'!K31="",'Глубина-день'!K30,'Глубина-день'!K30) -> 80 | AC16: =IF('Глубина-день'!L30="",'Глубина-день'!I30,'Глубина-день'!L30) -> 2 | AD16: =AC16/24+AD15 -> 0.58333333 | AE16: ='Глубина-день'!R30 -> 3 | AF16: =AE16/24+AF15 -> 1.125
X17: ='Глубина-день'!A31 -> 12 | Y17: ='Глубина-день'!H31 -> 80 | Z17: ='Глубина-день'!I31 -> 2 | AA17: =Z17/24+AA16 -> 1.2083333 | AB17: =IF('Глубина-день'!K32="",'Глубина-день'!K31,'Глубина-день'!K31) -> 80 | AC17: =IF('Глубина-день'!L31="",'Глубина-день'!I31,'Глубина-день'!L31) -> 0.75 | AD17: =AC17/24+AD16 -> 0.61458333 | AE17: ='Глубина-день'!R31 -> 2 | AF17: =AE17/24+AF16 -> 1.2083333
X18: ='Глубина-день'!A32 -> 13 | Y18: ='Глубина-день'!H32 -> 82 | Z18: ='Глубина-день'!I32 -> 2 | AA18: =Z18/24+AA17 -> 1.2916667 | AB18: =IF('Глубина-день'!K33="",'Глубина-день'!K32,'Глубина-день'!K32) -> 80 | AC18: =IF('Глубина-день'!L32="",'Глубина-день'!I32,'Глубина-день'!L32) -> 0.25 | AD18: =AC18/24+AD17 -> 0.625 | AE18: ='Глубина-день'!R32 -> 2 | AF18: =AE18/24+AF17 -> 1.2916667
... X38: ='Глубина-день'!A52 -> 33 | Y38: ='Глубина-день'!H52 -> 2543.15 | Z38: ='Глубина-день'!I52 -> 6 | AA38: =Z38/24+AA37 -> 9.2708333 | AB38: =IF('Глубина-день'!K53="",'Глубина-день'!K52,'Глубина-день'!K52) -> 2543 | AC38: =IF('Глубина-день'!L52="",'Глубина-день'!I52,'Глубина-день'!L52) -> 2 | AD38: =AC38/24+AD37 -> 5.8958333 | AE38: ='Глубина-день'!R52 -> 6 | AF38: =AE38/24+AF37 -> 9.2708333
B39: ='Глубина-день'!K7 -> План | D39: ='Глубина-день'!N7 -> 28.153125 | F39: ='Глубина-день'!K10 -> Скорость бурения, сут/1000м | G39: ='Глубина-день'!L10 -> План | I39: ='Глубина-день'!N10 -> 6.0414431 | X39: ='Глубина-день'!A53 -> 34 | Y39: ='Глубина-день'!H53 -> 2543.15 | Z39: ='Глубина-день'!I53 -> 2.5 | AA39: =Z39/24+AA38 -> 9.375 | AB39: =IF('Глубина-день'!K54="",'Глубина-день'!K53,'Глубина-день'!K53) -> 2543 | AC39: =IF('Глубина-день'!L53="",'Глубина-день'!I53,'Глубина-день'!L53) -> 2 | AD39: =AC39/24+AD38 -> 5.9791667 | AE39: ='Глубина-день'!R53 -> 2.5 | AF39: =AE39/24+AF38 -> 9.375
B40: ='Глубина-день'!K8 -> Факт/прогноз, сут | D40: ='Глубина-день'!N8 -> 17.5625 | G40: ='Глубина-день'!L11 -> Факт+Прогноз | I40: ='Глубина-день'!N11 -> 3.7687768 | X40: ='Глубина-день'!A54 -> 35 | Y40: ='Глубина-день'!H54 -> 2543.15 | Z40: ='Глубина-день'!I54 -> 14 | AA40: =Z40/24+AA39 -> 9.9583333 | AB40: =IF('Глубина-день'!K55="",'Глубина-день'!K54,'Глубина-день'!K54) -> 2543 | AC40: =IF('Глубина-день'!L54="",'Глубина-день'!I54,'Глубина-день'!L54) -> 2 | AD40: =AC40/24+AD39 -> 6.0625 | AE40: ='Глубина-день'!R54 -> 14 | AF40: =AE40/24+AF39 -> 9.9583333
B41: ='Глубина-день'!K9 -> План для бонуса | D41: ='Глубина-день'!N9 -> 28.153125 | G41: ='Глубина-день'!L12 -> План для бонуса | I41: ='Глубина-день'!N12 -> 6.0414431 | X41: ='Глубина-день'!A55 -> 36 | Y41: ='Глубина-день'!H55 -> 2543.15 | Z41: ='Глубина-день'!I55 -> 54 | AA41: =Z41/24+AA40 -> 12.208333 | AB41: =IF('Глубина-день'!K56="",'Глубина-день'!K55,'Глубина-день'!K55) -> 2543 | AC41: =IF('Глубина-день'!L55="",'Глубина-день'!I55,'Глубина-день'!L55) -> 36.75 | AD41: =AC41/24+AD40 -> 7.59375 | AE41: ='Глубина-день'!R55 -> 54 | AF41: =AE41/24+AF40 -> 12.208333
X42: ='Глубина-день'!A56 -> 37 | Y42: ='Глубина-день'!H56 -> 2543.15 | Z42: ='Глубина-день'!I56 -> 5 | AA42: =Z42/24+AA41 -> 12.416667 | AB42: =IF('Глубина-день'!K57="",'Глубина-день'!K56,'Глубина-день'!K56) -> 2543 | AC42: =IF('Глубина-день'!L56="",'Глубина-день'!I56,'Глубина-день'!L56) -> 4 | AD42: =AC42/24+AD41 -> 7.7604167 | AE42: ='Глубина-день'!R56 -> 5 | AF42: =AE42/24+AF41 -> 12.416667
X43: ='Глубина-день'!A57 -> 38 | Y43: ='Глубина-день'!H57 -> 2543.15 | Z43: ='Глубина-день'!I57 -> 16 | AA43: =Z43/24+AA42 -> 13.083333 | AB43: =IF('Глубина-день'!K58="",'Глубина-день'!K57,'Глубина-день'!K57) -> 2543 | AC43: =IF('Глубина-день'!L57="",'Глубина-день'!I57,'Глубина-день'!L57) -> 5 | AD43: =AC43/24+AD42 -> 7.96875 | AE43: ='Глубина-день'!R57 -> 16 | AF43: =AE43/24+AF42 -> 13.083333
X44: ='Глубина-день'!A58 -> 39 | Y44: ='Глубина-день'!H58 -> 2543.15 | Z44: ='Глубина-день'!I58 -> 2 | AA44: =Z44/24+AA43 -> 13.166667 | AB44: =IF('Глубина-день'!K59="",'Глубина-день'!K58,'Глубина-день'!K58) -> 2543 | AC44: =IF('Глубина-день'!L58="",'Глубина-день'!I58,'Глубина-день'!L58) -> 0 | AD44: =AC44/24+AD43 -> 7.96875 | AE44: ='Глубина-день'!R58 -> 2 | AF44: =AE44/24+AF43 -> 13.166667
X45: ='Глубина-день'!A59 -> 40 | Y45: ='Глубина-день'!H59 -> 2543.15 | Z45: ='Глубина-день'!I59 -> 3 | AA45: =Z45/24+AA44 -> 13.291667 | AB45: =IF('Глубина-день'!K60="",'Глубина-день'!K59,'Глубина-день'!K59) -> 2543 | AC45: =IF('Глубина-день'!L59="",'Глубина-день'!I59,'Глубина-день'!L59) -> 3 | AD45: =AC45/24+AD44 -> 8.09375 | AE45: ='Глубина-день'!R59 -> 3 | AF45: =AE45/24+AF44 -> 13.291667
X46: ='Глубина-день'!A60 -> 41 | Y46: ='Глубина-день'!H60 -> 2543.15 | Z46: ='Глубина-день'!I60 -> 2 | AA46: =Z46/24+AA45 -> 13.375 | AB46: =IF('Глубина-день'!K61="",'Глубина-день'!K60,'Глубина-день'!K60) -> 2543 | AC46: =IF('Глубина-день'!L60="",'Глубина-день'!I60,'Глубина-день'!L60) -> 2 | AD46: =AC46/24+AD45 -> 8.1770833 | AE46: ='Глубина-день'!R60 -> 2 | AF46: =AE46/24+AF45 -> 13.375
X47: ='Глубина-день'!A61 -> 42 | Y47: ='Глубина-день'!H61 -> 2543.15 | Z47: ='Глубина-день'!I61 -> 1 | AA47: =Z47/24+AA46 -> 13.416667 | AB47: =IF('Глубина-день'!K62="",'Глубина-день'!K61,'Глубина-день'!K61) -> 2543 | AC47: =IF('Глубина-день'!L61="",'Глубина-день'!I61,'Глубина-день'!L61) -> 1 | AD47: =AC47/24+AD46 -> 8.21875 | AE47: ='Глубина-день'!R61 -> 1 | AF47: =AE47/24+AF46 -> 13.416667
X48: ='Глубина-день'!A62 -> 43 | Y48: ='Глубина-день'!H62 -> 3110 | Z48: ='Глубина-день'!I62 -> 46 | AA48: =Z48/24+AA47 -> 15.333333 | AB48: =IF('Глубина-день'!K63="",'Глубина-день'!K62,'Глубина-день'!K62) -> 3107 | AC48: =IF('Глубина-день'!L62="",'Глубина-день'!I62,'Глубина-день'!L62) -> 34.5 | AD48: =AC48/24+AD47 -> 9.65625 | AE48: ='Глубина-день'!R62 -> 46 | AF48: =AE48/24+AF47 -> 15.333333
X49: ='Глубина-день'!A63 -> 44 | Y49: ='Глубина-день'!H63 -> 3110 | Z49: ='Глубина-день'!I63 -> 2 | AA49: =Z49/24+AA48 -> 15.416667 | AB49: =IF('Глубина-день'!K64="",'Глубина-день'!K63,'Глубина-день'!K63) -> 3107 | AC49: =IF('Глубина-день'!L63="",'Глубина-день'!I63,'Глубина-день'!L63) -> 0.75 | AD49: =AC49/24+AD48 -> 9.6875 | AE49: ='Глубина-день'!R63 -> 2 | AF49: =AE49/24+AF48 -> 15.416667
X50: ='Глубина-день'!A64 -> 45 | Y50: ='Глубина-день'!H64 -> 3110 | Z50: ='Глубина-день'!I64 -> 1 | AA50: =Z50/24+AA49 -> 15.458333 | AB50: =IF('Глубина-день'!K65="",'Глубина-день'!K64,'Глубина-день'!K64) -> 3107 | AC50: =IF('Глубина-день'!L64="",'Глубина-день'!I64,'Глубина-день'!L64) -> 0.5 | AD50: =AC50/24+AD49 -> 9.7083333 | AE50: ='Глубина-день'!R64 -> 1 | AF50: =AE50/24+AF49 -> 15.458333
X51: ='Глубина-день'!A65 -> 46 | Y51: ='Глубина-день'!H65 -> 4660 | Z51: ='Глубина-день'!I65 -> 130 | AA51: =Z51/24+AA50 -> 20.875 | AB51: =IF('Глубина-день'!K66="",'Глубина-день'!K65,'Глубина-день'!K65) -> 3501 | AC51: =IF('Глубина-день'!L65="",'Глубина-день'!I65,'Глубина-день'!L65) -> 46 | AD51: =AC51/24+AD50 -> 11.625 | AE51: ='Глубина-день'!R65 -> 130 | AF51: =AE51/24+AF50 -> 20.875
X52: ='Глубина-день'!A66 -> 47 | Y52: ='Глубина-день'!H66 -> 4660 | Z52: ='Глубина-день'!I66 -> 3 | AA52: =Z52/24+AA51 -> 21 | AB52: =IF('Глубина-день'!K67="",'Глубина-день'!K66,'Глубина-день'!K66) -> 0 | AC52: =IF('Глубина-день'!L66="",'Глубина-день'!I66,'Глубина-день'!L66) -> 3 | AD52: =AC52/24+AD51 -> 11.75 | AE52: ='Глубина-день'!R66 -> 3 | AF52: =AE52/24+AF51 -> 21
X53: ='Глубина-день'!A67 -> 48 | Y53: ='Глубина-день'!H67 -> 4660 | Z53: ='Глубина-день'!I67 -> 7 | AA53: =Z53/24+AA52 -> 21.291667 | AB53: =IF('Глубина-день'!K68="",'Глубина-день'!K67,'Глубина-день'!K67) -> 0 | AC53: =IF('Глубина-день'!L67="",'Глубина-день'!I67,'Глубина-день'!L67) -> 7 | AD53: =AC53/24+AD52 -> 12.041667 | AE53: ='Глубина-день'!R67 -> 7 | AF53: =AE53/24+AF52 -> 21.291667
... X68: ='Глубина-день'!A82 -> 63 | Y68: ='Глубина-день'!H82 -> 4660 | Z68: ='Глубина-день'!I82 -> 3 | AA68: =Z68/24+AA67 -> 26.8125 | AB68: =IF('Глубина-день'!K83="",'Глубина-день'!K82,'Глубина-день'!K82) -> 0 | AC68: =IF('Глубина-день'!L82="",'Глубина-день'!I82,'Глубина-день'!L82) -> 3 | AD68: =AC68/24+AD67 -> 17.5625 | AE68: ='Глубина-день'!R82 -> 3 | AF68: =AE68/24+AF67 -> 26.8125

Sheet реестр НПВ
A1: № НПВ | B1: Год | C1: Месяц | D1: Дата начала НПВ | E1: Дата окончания НПВ | F1: № скв | G1: № куста | H1: М-е | I1: Вид НПВ | J1: Классификация | K1: Расшифровка НПВ | L1: Виновная сторона | M1: НПВ, Простой, час
A3: 1 | B3: 2024 | C3: август | D3: 06.08.2024 15:00 06.08.2024 16:00 | E3: 06.08.2024 15:30 06.08.2024 16:00 | F3: 43820ГС | G3: 134В.1 | H3: Южно-Приобское | I3: Потеря сигнала Т/С | J3: Простои | K3: Не запланированное СПО в связи с отсутствием сигнала Т/С. | L3: ООО "НПП "Буринтех"
A4: 2
A5: 3
A6: 4
A7: 5
A8: 6
A9: 7
A10: 8
A11: 9
A12: 10
A13: 11
A14: 12
A15: 13
... A46: 44
L47: Общее НПВ по скв | M47: =SUM(M3:M43) -> 0
K49: Распределение НПВ по типам
K50: распределение НПВ по типам | L50: Аварии | M50: =SUMIFS($M$3:$M$46,$J$3:$J$46,L50) -> 0
L51: Осложнения | M51: =SUMIFS($M$3:$M$46,$J$3:$J$46,L51) -> 0
L52: Геологические осложнения | M52: =SUMIFS($M$3:$M$46,$J$3:$J$46,L52) -> 0
L53: Ликв.брака | M53: =SUMIFS($M$3:$M$46,$J$3:$J$46,L53) -> 0
L54: Простои | M54: =SUMIFS($M$3:$M$46,$J$3:$J$46,L54) -> 0
L55: Простои метео | M55: =SUMIFS($M$3:$M$46,$J$3:$J$46,L55) -> 0
L56: Ремонт ББ | M56: =SUMIFS($M$3:$M$46,$J$3:$J$46,L56) -> 0
L57: НПВ 1 | M57: =SUMIFS($M$3:$M$46,$J$3:$J$46,L57) -> 0
L58: НПВ 2 | M58: =SUMIFS($M$3:$M$46,$J$3:$J$46,L58) -> 0
L59: итого | M59: =SUM(M50:M58) -> 0
K61: Распределение НПВ по ПО
K62: распределение НПВ по ПО (можно менять нименования) | L62: ООО "НТ-Сервис" | M62: =SUMIFS($M$3:$M$46,$L$3:$L$46,L62) -> 0
L63: НФ ООО "БКЕ" | M63: =SUMIFS($M$3:$M$46,$L$3:$L$46,L63) -> 0
L64: ООО "НПП "Буринтех" | M64: =SUMIFS($M$3:$M$46,$L$3:$L$46,L64) -> 0
L65: ООО "Траектория-сервис" | M65: =SUMIFS($M$3:$M$46,$L$3:$L$46,L65) -> 0
L66: АО "НПП "Бурсервис" | M66: =SUMIFS($M$3:$M$46,$L$3:$L$46,L66) -> 0
L67: ООО "Бренд Фактор" | M67: =SUMIFS($M$3:$M$46,$L$3:$L$46,L67) -> 0
L68: ООО "НОРД-СЕРВИС" | M68: =SUMIFS($M$3:$M$46,$L$3:$L$46,L68) -> 0
L69: ООО "Зенит-Сервис" | M69: =SUMIFS($M$3:$M$46,$L$3:$L$46,L69) -> 0
L70: ПО 1 | M70: =SUMIFS($M$3:$M$46,$L$3:$L$46,L70) -> 0
L71: ПО 2 | M71: =SUMIFS($M$3:$M$46,$L$3:$L$46,L71) -> 0
L72: ПО 3 | M72: =SUMIFS($M$3:$M$46,$L$3:$L$46,L72) -> 0
L73: ПО 4 | M73: =SUMIFS($M$3:$M$46,$L$3:$L$46,L73) -> 0
...
